Workbook

Sheet Lisez-moi
A1: Calcul de reference au tableur des indicateurs du tableau de bord.
A3: Le critere d'achevement du sprint 7 exige que les treize indicateurs affiches
A4: concordent avec un calcul de reference etabli au tableur, a trois dates.
A5: Ce script construit ce classeur :
A7: 1. il extrait de la base les SEULES donnees sources — quantitatif, dates
A8: prevues, methodes d'avancement, releves valides, moyens, aleas, equipes
A9: affectees — sans lire aucune valeur derivee ni aucun instantane ;
A10: 2. il ecrit un classeur dont chaque grandeur est une FORMULE du tableur,
A11: redigee d'apres les regles de la conception (sections 4.1 a 4.3) et non
A12: d'apres le code de l'application ;
A13: 3. il fait recalculer le classeur par LibreOffice, sans interface, et relit
A14: les valeurs obtenues dans `docs/reference/indicateurs.json`.
... A28: Dependances : psql, LibreOffice (soffice) et le module openpyxl.

Sheet Indicateurs
A1: Indicateur | B1: Clé | C1: 2026-05-15 | D1: 2026-07-31 | E1: 2026-09-27
A2: Jour d'analyse | B2: jour | C2: =Dates!$B$2 -> 74 | D2: =Dates!$B$3 -> 151 | E2: =Dates!$B$4 -> 209
A3: Délai en vigueur, jours | B3: dureeContrat | C3: =Parametres!$B$10+SUMIFS(Actes!$C$2:$C$6,Actes!$A$2:$A$6,"AVENANT",Actes!$B$2:$B$6,"<="&Dates!$A$2)+SUMIFS(Actes!$C$2:$C$6,Actes!$A$2:$A$6,"PROLONGATION",Actes!$B$2:$B$6,"<="&Dates!$A$2)+MAX(0,SUMIFS(Actes!$C$2:$C$6,Actes!$A$2:$A$6,"INTEMPERIE",Actes!$B$2:$B$6,"<="&Dates!$A$2)-Parametres!$B$13) -> 412 | D3: =Parametres!$B$10+SUMIFS(Actes!$C$2:$C$6,Actes!$A$2:$A$6,"AVENANT",Actes!$B$2:$B$6,"<="&Dates!$A$3)+SUMIFS(Actes!$C$2:$C$6,Actes!$A$2:$A$6,"PROLONGATION",Actes!$B$2:$B$6,"<="&Dates!$A$3)+MAX(0,SUMIFS(Actes!$C$2:$C$6,Actes!$A$2:$A$6,"INTEMPERIE",Actes!$B$2:$B$6,"<="&Dates!$A$3)-Parametres!$B$13) -> 416 | E3: =Parametres!$B$10+SUMIFS(Actes!$C$2:$C$6,Actes!$A$2:$A$6,"AVENANT",Actes!$B$2:$B$6,"<="&Dates!$A$4)+SUMIFS(Actes!$C$2:$C$6,Actes!$A$2:$A$6,"PROLONGATION",Actes!$B$2:$B$6,"<="&Dates!$A$4)+MAX(0,SUMIFS(Actes!$C$2:$C$6,Actes!$A$2:$A$6,"INTEMPERIE",Actes!$B$2:$B$6,"<="&Dates!$A$4)-Parametres!$B$13) -> 416
A4: Montant du marché en vigueur, FCFA | B4: montantContrat | C4: =Parametres!$B$11+SUMIFS(Actes!$D$2:$D$6,Actes!$A$2:$A$6,"AVENANT",Actes!$B$2:$B$6,"<="&Dates!$A$2) -> 1156141200 | D4: =Parametres!$B$11+SUMIFS(Actes!$D$2:$D$6,Actes!$A$2:$A$6,"AVENANT",Actes!$B$2:$B$6,"<="&Dates!$A$3) -> 1156141200 | E4: =Parametres!$B$11+SUMIFS(Actes!$D$2:$D$6,Actes!$A$2:$A$6,"AVENANT",Actes!$B$2:$B$6,"<="&Dates!$A$4) -> 1156141200
A5: BAC, budget à l'achèvement | B5: bac | C5: =SUM(Taches!$G$2:$G$60) -> 1156141200 | D5: =SUM(Taches!$G$2:$G$60) -> 1156141200 | E5: =SUM(Taches!$G$2:$G$60) -> 1156141200
A6: Budget au coût du projet | B6: budgetCout | C6: =SUM(Lots!$E$2:$E$9)+ROUND(Parametres!$B$10*Parametres!$B$5,0) -> 992847096 | D6: =SUM(Lots!$E$2:$E$9)+ROUND(Parametres!$B$10*Parametres!$B$5,0) -> 992847096 | E6: =SUM(Lots!$E$2:$E$9)+ROUND(Parametres!$B$10*Parametres!$B$5,0) -> 992847096
A7: k, coefficient de déboursé | B7: k | C7: =C6/C5 -> 0.85875938 | D7: =D6/D5 -> 0.85875938 | E7: =E6/E5 -> 0.85875938
A8: VP, valeur planifiée | B8: vp | C8: =SUM(Lots!J2:J9) -> 155926975 | D8: =SUM(Lots!R2:R9) -> 347067400 | E8: =SUM(Lots!Z2:Z9) -> 557272121
A9: VA, valeur acquise | B9: va | C9: =SUM(Lots!I2:I9) -> 142394678 | D9: =SUM(Lots!Q2:Q9) -> 321113498 | E9: =SUM(Lots!Y2:Y9) -> 504483806
A10: CR, coût réel | B10: cr | C10: =SUM(Lots!M2:M9)+(C2+1)*Parametres!$B$5+SUMIFS(Aleas!$C$2:$C$13,Aleas!$A$2:$A$13,"SANS-LOT",Aleas!$B$2:$B$13,"<="&Dates!$A$2) -> 132154017 | D10: =SUM(Lots!U2:U9)+(D2+1)*Parametres!$B$5+SUMIFS(Aleas!$C$2:$C$13,Aleas!$A$2:$A$13,"SANS-LOT",Aleas!$B$2:$B$13,"<="&Dates!$A$3) -> 315532211 | E10: =SUM(Lots!AC2:AC9)+(E2+1)*Parametres!$B$5+SUMIFS(Aleas!$C$2:$C$13,Aleas!$A$2:$A$13,"SANS-LOT",Aleas!$B$2:$B$13,"<="&Dates!$A$4) -> 481218198
A11: Avancement réel | B11: avancement | C11: =C9/C5 -> 0.12316374 | D11: =D9/D5 -> 0.27774592 | E11: =E9/E5 -> 0.43635138
A12: EC, écart de coût | B12: ecartCout | C12: =ROUND(C7*C9-C10,0) -> -9871252 | D12: =ROUND(D7*D9-D10,0) -> -39772984 | E12: =ROUND(E7*E9-E10,0) -> -47987999
A13: ED, écart de délai en valeur | B13: ecartDelaiValeur | C13: =C9-C8 -> -13532297 | D13: =D9-D8 -> -25953902 | E13: =E9-E8 -> -52788315
A14: CPI | B14: cpi | C14: =C7*C9/C10 -> 0.92530494 | D14: =D7*D9/D10 -> 0.87394953 | E14: =E7*E9/E10 -> 0.90027809
A15: SPI | B15: spi | C15: =C9/C8 -> 0.91321388 | D15: =D9/D8 -> 0.92521942 | E15: =E9/E8 -> 0.90527372
A16: BAC au coût | B16: bacCout | C16: =ROUND(C7*C5,0) -> 992847096 | D16: =ROUND(D7*D5,0) -> 992847096 | E16: =ROUND(E7*E5,0) -> 992847096
A17: EAC, coût estimé final | B17: eac | C17: =ROUND(C16/C14,0) -> 1072994482 | D17: =ROUND(D16/D14,0) -> 1136046262 | E17: =ROUND(E16/E14,0) -> 1102822684
A18: ETC, reste à dépenser | B18: etc | C18: =C17-C10 -> 940840465 | D18: =D17-D10 -> 820514051 | E18: =E17-E10 -> 621604486
A19: VAC, écart final | B19: vac | C19: =C16-C17 -> -80147386 | D19: =D16-D17 -> -143199166 | E19: =E16-E17 -> -109975588
A20: Durée projetée, jours | B20: dureeProjeteeJ | C20: =ROUND(C3/C15,0) -> 451 | D20: =ROUND(D3/D15,0) -> 450 | E20: =ROUND(E3/E15,0) -> 460
A21: Retard estimé, jours | B21: retardJ | C21: =MAX(0,C20-C3) -> 39 | D21: =MAX(0,D20-D3) -> 34 | E21: =MAX(0,E20-E3) -> 44
A22: Pénalité prévue, FCFA | B22: penaliteXof | C22: =ROUND(C21*Parametres!$B$12*C4,0) -> 45089507 | D22: =ROUND(D21*Parametres!$B$12*D4,0) -> 39308801 | E22: =ROUND(E21*Parametres!$B$12*E4,0) -> 50870213
A23: Rang t' sur la courbe planifiée | B23: rang | C23: =MATCH(C9,CourbeVP!$J$2:INDEX(CourbeVP!$J:$J,C2+2),1)-1 -> 70 | D23: =MATCH(D9,CourbeVP!$J$2:INDEX(CourbeVP!$J:$J,D2+2),1)-1 -> 138 | E23: =MATCH(E9,CourbeVP!$J$2:INDEX(CourbeVP!$J:$J,E2+2),1)-1 -> 195
A24: Écart de délai en jours, lecture horizontale | B24: ecartDelaiJ | C24: =C2-(C23+IF(INDEX(CourbeVP!$J:$J,C23+2)=C9,0,(C9-INDEX(CourbeVP!$J:$J,C23+2))/(INDEX(CourbeVP!$J:$J,C23+3)-INDEX(CourbeVP!$J:$J,C23+2)))) -> 3.9966322 | D24: =D2-(D23+IF(INDEX(CourbeVP!$J:$J,D23+2)=D9,0,(D9-INDEX(CourbeVP!$J:$J,D23+2))/(INDEX(CourbeVP!$J:$J,D23+3)-INDEX(CourbeVP!$J:$J,D23+2)))) -> 12.748774 | E24: =E2-(E23+IF(INDEX(CourbeVP!$J:$J,E23+2)=E9,0,(E9-INDEX(CourbeVP!$J:$J,E23+2))/(INDEX(CourbeVP!$J:$J,E23+3)-INDEX(CourbeVP!$J:$J,E23+2)))) -> 13.669006

Sheet Parametres
A1: Paramètre | B1: Valeur
A2: Taux horaire ouvrier, FCFA | B2: 1400
A3: Coût journalier d'un encadrant, FCFA | B3: 42000
A4: Part matériaux du prix unitaire | B4: 0.58
A5: Frais de chantier par jour calendaire, FCFA | B5: 300000
A6: Heures planifiées par ouvrier et par jour | B6: 8
A7: Ouvriers par encadrant | B7: 12
A8: Projet
A9: Ordre de service | B9: 46083
A10: Durée contractuelle, jours | B10: 412
A11: Montant du marché, FCFA | B11: 1156141200
A12: Pénalité journalière, fraction du marché | B12: 0.001
A13: Intempéries prévisibles au CCAP, jours | B13: 6

Sheet Dates
A1: Date d'analyse | B1: Jour depuis l'ordre de service
A2: 46157 | B2: =A2-Parametres!$B$9 -> 74
A3: 46234 | B3: =A3-Parametres!$B$9 -> 151
A4: 46292 | B4: =A4-Parametres!$B$9 -> 209

Sheet Actes
A1: Nature | B1: Date | C1: Jours | D1: Montant, FCFA
A2: INTEMPERIE | B2: 46120 | C2: 1 | D2: 0
A3: INTEMPERIE | B3: 46167 | C3: 1 | D3: 0
A4: INTEMPERIE | B4: 46177 | C4: 1 | D4: 0
A5: INTEMPERIE | B5: 46188 | C5: 6 | D5: 0
A6: INTEMPERIE | B6: 46202 | C6: 1 | D6: 0

Sheet Quantites
A1: Ligne | B1: Date | C1: Quantité validée
A2: Q001 | B2: 46083 | C2: 20.669
A3: Q002 | B3: 46083 | C3: 50.877
A4: Q003 | B4: 46083 | C4: 0.159
A5: Q001 | B5: 46084 | C5: 28.07
A6: Q002 | B6: 46084 | C6: 69.095
A7: Q003 | B7: 46084 | C7: 0.216
A8: Q001 | B8: 46085 | C8: 28.645
A9: Q002 | B9: 46085 | C9: 70.511
A10: Q003 | B10: 46085 | C10: 0.22
A11: Q001 | B11: 46086 | C11: 26.603
A12: Q002 | B12: 46086 | C12: 65.486
A13: Q003 | B13: 46086 | C13: 0.205
... A1166: Q080 | B1166: 46292 | C1166: 60.251

Sheet Moyens
A1: Lot | B1: Date | C1: Heures ouvriers | D1: Encadrants
A2: LOT-01 | B2: 46083 | C2: 37.82 | D2: 2
A3: LOT-01 | B3: 46084 | C3: 24.06 | D3: 2
A4: LOT-01 | B4: 46085 | C4: 51.6 | D4: 2
A5: LOT-01 | B5: 46086 | C5: 53.49 | D5: 2
A6: LOT-01 | B6: 46087 | C6: 53.39 | D6: 2
A7: LOT-01 | B7: 46088 | C7: 57.32 | D7: 2
A8: LOT-01 | B8: 46089 | C8: 46.59 | D8: 2
A9: LOT-01 | B9: 46090 | C9: 33.47 | D9: 2
A10: LOT-01 | B10: 46091 | C10: 48.56 | D10: 2
A11: LOT-01 | B11: 46092 | C11: 55.85 | D11: 2
A12: LOT-01 | B12: 46093 | C12: 50.67 | D12: 2
A13: LOT-01 | B13: 46094 | C13: 52.51 | D13: 2
... A349: LOT-07 | B349: 46292 | C349: 154.75 | D349: 3

Sheet Aleas
A1: Lot | B1: Date | C1: Impact de coût
A2: LOT-02 | B2: 46120 | C2: 1850000
A3: LOT-03 | B3: 46134 | C3: 2400000
A4: LOT-04 | B4: 46153 | C4: 4200000
A5: LOT-03 | B5: 46167 | C5: 1850000
A6: LOT-04 | B6: 46175 | C6: 1150000
A7: LOT-03 | B7: 46177 | C7: 1850000
A8: SANS-LOT | B8: 46188 | C8: 11100000
A9: LOT-04 | B9: 46188 | C9: 5100000
A10: SANS-LOT | B10: 46202 | C10: 1850000
A11: LOT-04 | B11: 46217 | C11: 3800000
A12: LOT-02 | B12: 46260 | C12: 1650000
A13: LOT-04 | B13: 46280 | C13: 890000

Sheet Equipes
A1: Lot | B1: Début | C1: Fin | D1: Ouvriers
A2: LOT-01 | B2: 46083 | C2: 46092 | D2: 5
A3: LOT-01 | B3: 46093 | C3: 46104 | D3: 5
A4: LOT-01 | B4: 46105 | C4: 46112 | D4: 5
A5: LOT-01 | B5: 46105 | C5: 46110 | D5: 4
A6: LOT-01 | B6: 46485 | C6: 46494 | D6: 5
A7: LOT-02 | B7: 46093 | C7: 46100 | D7: 8
A8: LOT-02 | B8: 46101 | C8: 46118 | D8: 8
A9: LOT-02 | B9: 46119 | C9: 46132 | D9: 8
A10: LOT-02 | B10: 46181 | C10: 46192 | D10: 8
A11: LOT-02 | B11: 46193 | C11: 46207 | D11: 6
A12: LOT-02 | B12: 46203 | C12: 46212 | D12: 6
A13: LOT-02 | B13: 46208 | C13: 46219 | D13: 6
... A60: LOT-08 | B60: 46467 | C60: 46484 | D60: 6

Sheet Engins
A1: Lot | B1: Date | C1: Heures | D1: Coût unitaire | E1: Unité | F1: Coût
A2: LOT-02 | B2: 46094 | C2: 14.6 | D2: 118000 | E2: JOUR | F2: =IF(E2="HEURE",C2*D2,IF(E2="JOUR",C2/Parametres!$B$6*D2,0)) -> 215350
A3: LOT-02 | B3: 46094 | C3: 8.3 | D3: 265000 | E3: JOUR | F3: =IF(E3="HEURE",C3*D3,IF(E3="JOUR",C3/Parametres!$B$6*D3,0)) -> 274937.5
A4: LOT-02 | B4: 46095 | C4: 13.8 | D4: 118000 | E4: JOUR | F4: =IF(E4="HEURE",C4*D4,IF(E4="JOUR",C4/Parametres!$B$6*D4,0)) -> 203550
A5: LOT-02 | B5: 46095 | C5: 7.1 | D5: 265000 | E5: JOUR | F5: =IF(E5="HEURE",C5*D5,IF(E5="JOUR",C5/Parametres!$B$6*D5,0)) -> 235187.5
A6: LOT-02 | B6: 46096 | C6: 15.7 | D6: 118000 | E6: JOUR | F6: =IF(E6="HEURE",C6*D6,IF(E6="JOUR",C6/Parametres!$B$6*D6,0)) -> 231575
A7: LOT-02 | B7: 46096 | C7: 7.7 | D7: 265000 | E7: JOUR | F7: =IF(E7="HEURE",C7*D7,IF(E7="JOUR",C7/Parametres!$B$6*D7,0)) -> 255062.5
A8: LOT-02 | B8: 46097 | C8: 14.2 | D8: 118000 | E8: JOUR | F8: =IF(E8="HEURE",C8*D8,IF(E8="JOUR",C8/Parametres!$B$6*D8,0)) -> 209450
A9: LOT-02 | B9: 46097 | C9: 7.4 | D9: 265000 | E9: JOUR | F9: =IF(E9="HEURE",C9*D9,IF(E9="JOUR",C9/Parametres!$B$6*D9,0)) -> 245125
A10: LOT-02 | B10: 46098 | C10: 15 | D10: 118000 | E10: JOUR | F10: =IF(E10="HEURE",C10*D10,IF(E10="JOUR",C10/Parametres!$B$6*D10,0)) -> 221250
A11: LOT-02 | B11: 46098 | C11: 8.1 | D11: 265000 | E11: JOUR | F11: =IF(E11="HEURE",C11*D11,IF(E11="JOUR",C11/Parametres!$B$6*D11,0)) -> 268312.5
A12: LOT-02 | B12: 46099 | C12: 14.1 | D12: 118000 | E12: JOUR | F12: =IF(E12="HEURE",C12*D12,IF(E12="JOUR",C12/Parametres!$B$6*D12,0)) -> 207975
A13: LOT-02 | B13: 46099 | C13: 6.9 | D13: 265000 | E13: JOUR | F13: =IF(E13="HEURE",C13*D13,IF(E13="JOUR",C13/Parametres!$B$6*D13,0)) -> 228562.5
... A149: LOT-02 | B149: 46247 | C149: 7 | D149: 265000 | E149: JOUR | F149: =IF(E149="HEURE",C149*D149,IF(E149="JOUR",C149/Parametres!$B$6*D149,0)) -> 231875

Sheet EnginsPrevus
A1: Lot | B1: Début | C1: Fin | D1: Quantité | E1: Coût unitaire | F1: Unité | G1: Coût prévu
A2: LOT-02 | B2: 46093 | C2: 46100 | D2: 2 | E2: 118000 | F2: JOUR | G2: =(C2-B2+1)*D2*IF(F2="JOUR",E2,IF(F2="HEURE",Parametres!$B$6*E2,0)) -> 1888000
A3: LOT-02 | B3: 46093 | C3: 46100 | D3: 1 | E3: 265000 | F3: JOUR | G3: =(C3-B3+1)*D3*IF(F3="JOUR",E3,IF(F3="HEURE",Parametres!$B$6*E3,0)) -> 2120000
A4: LOT-02 | B4: 46101 | C4: 46118 | D4: 2 | E4: 118000 | F4: JOUR | G4: =(C4-B4+1)*D4*IF(F4="JOUR",E4,IF(F4="HEURE",Parametres!$B$6*E4,0)) -> 4248000
A5: LOT-02 | B5: 46101 | C5: 46118 | D5: 1 | E5: 265000 | F5: JOUR | G5: =(C5-B5+1)*D5*IF(F5="JOUR",E5,IF(F5="HEURE",Parametres!$B$6*E5,0)) -> 4770000
A6: LOT-02 | B6: 46119 | C6: 46132 | D6: 2 | E6: 118000 | F6: JOUR | G6: =(C6-B6+1)*D6*IF(F6="JOUR",E6,IF(F6="HEURE",Parametres!$B$6*E6,0)) -> 3304000
A7: LOT-02 | B7: 46119 | C7: 46132 | D7: 1 | E7: 265000 | F7: JOUR | G7: =(C7-B7+1)*D7*IF(F7="JOUR",E7,IF(F7="HEURE",Parametres!$B$6*E7,0)) -> 3710000
A8: LOT-02 | B8: 46181 | C8: 46192 | D8: 2 | E8: 118000 | F8: JOUR | G8: =(C8-B8+1)*D8*IF(F8="JOUR",E8,IF(F8="HEURE",Parametres!$B$6*E8,0)) -> 2832000
A9: LOT-02 | B9: 46181 | C9: 46192 | D9: 1 | E9: 265000 | F9: JOUR | G9: =(C9-B9+1)*D9*IF(F9="JOUR",E9,IF(F9="HEURE",Parametres!$B$6*E9,0)) -> 3180000
A10: LOT-02 | B10: 46193 | C10: 46207 | D10: 1 | E10: 265000 | F10: JOUR | G10: =(C10-B10+1)*D10*IF(F10="JOUR",E10,IF(F10="HEURE",Parametres!$B$6*E10,0)) -> 3975000
A11: LOT-02 | B11: 46203 | C11: 46212 | D11: 1 | E11: 265000 | F11: JOUR | G11: =(C11-B11+1)*D11*IF(F11="JOUR",E11,IF(F11="HEURE",Parametres!$B$6*E11,0)) -> 2650000
A12: LOT-02 | B12: 46208 | C12: 46219 | D12: 1 | E12: 265000 | F12: JOUR | G12: =(C12-B12+1)*D12*IF(F12="JOUR",E12,IF(F12="HEURE",Parametres!$B$6*E12,0)) -> 3180000
A13: LOT-02 | B13: 46220 | C13: 46229 | D13: 1 | E13: 265000 | F13: JOUR | G13: =(C13-B13+1)*D13*IF(F13="JOUR",E13,IF(F13="HEURE",Parametres!$B$6*E13,0)) -> 2650000
... A16: LOT-08 | B16: 46467 | C16: 46484 | D16: 1 | E16: 265000 | F16: JOUR | G16: =(C16-B16+1)*D16*IF(F16="JOUR",E16,IF(F16="HEURE",Parametres!$B$6*E16,0)) -> 4770000

Sheet Lignes
A1: Clé | B1: Tâche | C1: Lot | D1: Désignation | E1: Quantité prévue | F1: Prix unitaire | G1: Montant | H1: Cumul au 2026-05-15 | I1: Acquis au 2026-05-15 | J1: Achevée au 2026-05-15 | K1: Dépassement au 2026-05-15 | L1: Cumul au 2026-07-31 | M1: Acquis au 2026-07-31 | N1: Achevée au 2026-07-31 | O1: Dépassement au 2026-07-31 | P1: Cumul au 2026-09-27 | Q1: Acquis au 2026-09-27 | R1: Achevée au 2026-09-27 | S1: Dépassement au 2026-09-27
A2: Q001 | B2: T-01.1.1 | C2: LOT-01 | D2: Clôture de chantier en tôle | E2: 260 | F2: 28000 | G2: =E2*F2 -> 7280000 | H2: =SUMIFS(Quantites!$C$2:$C$1166,Quantites!$A$2:$A$1166,A2,Quantites!$B$2:$B$1166,"<="&Dates!$A$2) -> 260 | I2: =MIN(H2,E2)*F2 -> 7280000 | J2: =IF(H2>=E2-0.000001,1,0) -> 1 | K2: =MAX(0,H2-E2)*F2 -> 0 | L2: =SUMIFS(Quantites!$C$2:$C$1166,Quantites!$A$2:$A$1166,A2,Quantites!$B$2:$B$1166,"<="&Dates!$A$3) -> 260 | M2: =MIN(L2,E2)*F2 -> 7280000 | N2: =IF(L2>=E2-0.000001,1,0) -> 1 | O2: =MAX(0,L2-E2)*F2 -> 0 | P2: =SUMIFS(Quantites!$C$2:$C$1166,Quantites!$A$2:$A$1166,A2,Quantites!$B$2:$B$1166,"<="&Dates!$A$4) -> 260 | Q2: =MIN(P2,E2)*F2 -> 7280000 | R2: =IF(P2>=E2-0.000001,1,0) -> 1 | S2: =MAX(0,P2-E2)*F2 -> 0
A3: Q002 | B3: T-01.1.1 | C3: LOT-01 | D3: Piste de circulation empierrée | E3: 640 | F3: 14000 | G3: =E3*F3 -> 8960000 | H3: =SUMIFS(Quantites!$C$2:$C$1166,Quantites!$A$2:$A$1166,A3,Quantites!$B$2:$B$1166,"<="&Dates!$A$2) -> 640 | I3: =MIN(H3,E3)*F3 -> 8960000 | J3: =IF(H3>=E3-0.000001,1,0) -> 1 | K3: =MAX(0,H3-E3)*F3 -> 0 | L3: =SUMIFS(Quantites!$C$2:$C$1166,Quantites!$A$2:$A$1166,A3,Quantites!$B$2:$B$1166,"<="&Dates!$A$3) -> 640 | M3: =MIN(L3,E3)*F3 -> 8960000 | N3: =IF(L3>=E3-0.000001,1,0) -> 1 | O3: =MAX(0,L3-E3)*F3 -> 0 | P3: =SUMIFS(Quantites!$C$2:$C$1166,Quantites!$A$2:$A$1166,A3,Quantites!$B$2:$B$1166,"<="&Dates!$A$4) -> 640 | Q3: =MIN(P3,E3)*F3 -> 8960000 | R3: =IF(P3>=E3-0.000001,1,0) -> 1 | S3: =MAX(0,P3-E3)*F3 -> 0
A4: Q003 | B4: T-01.1.1 | C4: LOT-01 | D4: Portail de chantier et accès | E4: 2 | F4: 850000 | G4: =E4*F4 -> 1700000 | H4: =SUMIFS(Quantites!$C$2:$C$1166,Quantites!$A$2:$A$1166,A4,Quantites!$B$2:$B$1166,"<="&Dates!$A$2) -> 2 | I4: =MIN(H4,E4)*F4 -> 1700000 | J4: =IF(H4>=E4-0.000001,1,0) -> 1 | K4: =MAX(0,H4-E4)*F4 -> 0 | L4: =SUMIFS(Quantites!$C$2:$C$1166,Quantites!$A$2:$A$1166,A4,Quantites!$B$2:$B$1166,"<="&Dates!$A$3) -> 2 | M4: =MIN(L4,E4)*F4 -> 1700000 | N4: =IF(L4>=E4-0.000001,1,0) -> 1 | O4: =MAX(0,L4-E4)*F4 -> 0 | P4: =SUMIFS(Quantites!$C$2:$C$1166,Quantites!$A$2:$A$1166,A4,Quantites!$B$2:$B$1166,"<="&Dates!$A$4) -> 2 | Q4: =MIN(P4,E4)*F4 -> 1700000 | R4: =IF(P4>=E4-0.000001,1,0) -> 1 | S4: =MAX(0,P4-E4)*F4 -> 0
A5: Q004 | B5: T-01.1.2 | C5: LOT-01 | D5: Aire de stockage et de ferraillage | E5: 380 | F5: 12000 | G5: =E5*F5 -> 4560000 | H5: =SUMIFS(Quantites!$C$2:$C$1166,Quantites!$A$2:$A$1166,A5,Quantites!$B$2:$B$1166,"<="&Dates!$A$2) -> 380 | I5: =MIN(H5,E5)*F5 -> 4560000 | J5: =IF(H5>=E5-0.000001,1,0) -> 1 | K5: =MAX(0,H5-E5)*F5 -> 0 | L5: =SUMIFS(Quantites!$C$2:$C$1166,Quantites!$A$2:$A$1166,A5,Quantites!$B$2:$B$1166,"<="&Dates!$A$3) -> 380 | M5: =MIN(L5,E5)*F5 -> 4560000 | N5: =IF(L5>=E5-0.000001,1,0) -> 1 | O5: =MAX(0,L5-E5)*F5 -> 0 | P5: =SUMIFS(Quantites!$C$2:$C$1166,Quantites!$A$2:$A$1166,A5,Quantites!$B$2:$B$1166,"<="&Dates!$A$4) -> 380 | Q5: =MIN(P5,E5)*F5 -> 4560000 | R5: =IF(P5>=E5-0.000001,1,0) -> 1 | S5: =MAX(0,P5-E5)*F5 -> 0
A6: Q005 | B6: T-01.1.2 | C6: LOT-01 | D6: Bungalows bureaux et réunion | E6: 4 | F6: 1850000 | G6: =E6*F6 -> 7400000 | H6: =SUMIFS(Quantites!$C$2:$C$1166,Quantites!$A$2:$A$1166,A6,Quantites!$B$2:$B$1166,"<="&Dates!$A$2) -> 4 | I6: =MIN(H6,E6)*F6 -> 7400000 | J6: =IF(H6>=E6-0.000001,1,0) -> 1 | K6: =MAX(0,H6-E6)*F6 -> 0 | L6: =SUMIFS(Quantites!$C$2:$C$1166,Quantites!$A$2:$A$1166,A6,Quantites!$B$2:$B$1166,"<="&Dates!$A$3) -> 4 | M6: =MIN(L6,E6)*F6 -> 7400000 | N6: =IF(L6>=E6-0.000001,1,0) -> 1 | O6: =MAX(0,L6-E6)*F6 -> 0 | P6: =SUMIFS(Quantites!$C$2:$C$1166,Quantites!$A$2:$A$1166,A6,Quantites!$B$2:$B$1166,"<="&Dates!$A$4) -> 4 | Q6: =MIN(P6,E6)*F6 -> 7400000 | R6: =IF(P6>=E6-0.000001,1,0) -> 1 | S6: =MAX(0,P6-E6)*F6 -> 0
A7: Q006 | B7: T-01.1.2 | C7: LOT-01 | D7: Vestiaires et sanitaires de chantier | E7: 3 | F7: 1200000 | G7: =E7*F7 -> 3600000 | H7: =SUMIFS(Quantites!$C$2:$C$1166,Quantites!$A$2:$A$1166,A7,Quantites!$B$2:$B$1166,"<="&Dates!$A$2) -> 3 | I7: =MIN(H7,E7)*F7 -> 3600000 | J7: =IF(H7>=E7-0.000001,1,0) -> 1 | K7: =MAX(0,H7-E7)*F7 -> 0 | L7: =SUMIFS(Quantites!$C$2:$C$1166,Quantites!$A$2:$A$1166,A7,Quantites!$B$2:$B$1166,"<="&Dates!$A$3) -> 3 | M7: =MIN(L7,E7)*F7 -> 3600000 | N7: =IF(L7>=E7-0.000001,1,0) -> 1 | O7: =MAX(0,L7-E7)*F7 -> 0 | P7: =SUMIFS(Quantites!$C$2:$C$1166,Quantites!$A$2:$A$1166,A7,Quantites!$B$2:$B$1166,"<="&Dates!$A$4) -> 3 | Q7: =MIN(P7,E7)*F7 -> 3600000 | R7: =IF(P7>=E7-0.000001,1,0) -> 1 | S7: =MAX(0,P7-E7)*F7 -> 0
A8: Q007 | B8: T-01.1.3 | C8: LOT-01 | D8: Branchement eau provisoire | E8: 1 | F8: 1900000 | G8: =E8*F8 -> 1900000 | H8: =SUMIFS(Quantites!$C$2:$C$1166,Quantites!$A$2:$A$1166,A8,Quantites!$B$2:$B$1166,"<="&Dates!$A$2) -> 1 | I8: =MIN(H8,E8)*F8 -> 1900000 | J8: =IF(H8>=E8-0.000001,1,0) -> 1 | K8: =MAX(0,H8-E8)*F8 -> 0 | L8: =SUMIFS(Quantites!$C$2:$C$1166,Quantites!$A$2:$A$1166,A8,Quantites!$B$2:$B$1166,"<="&Dates!$A$3) -> 1 | M8: =MIN(L8,E8)*F8 -> 1900000 | N8: =IF(L8>=E8-0.000001,1,0) -> 1 | O8: =MAX(0,L8-E8)*F8 -> 0 | P8: =SUMIFS(Quantites!$C$2:$C$1166,Quantites!$A$2:$A$1166,A8,Quantites!$B$2:$B$1166,"<="&Dates!$A$4) -> 1 | Q8: =MIN(P8,E8)*F8 -> 1900000 | R8: =IF(P8>=E8-0.000001,1,0) -> 1 | S8: =MAX(0,P8-E8)*F8 -> 0
A9: Q008 | B9: T-01.1.3 | C9: LOT-01 | D9: Branchement électrique provisoire | E9: 1 | F9: 4600000 | G9: =E9*F9 -> 4600000 | H9: =SUMIFS(Quantites!$C$2:$C$1166,Quantites!$A$2:$A$1166,A9,Quantites!$B$2:$B$1166,"<="&Dates!$A$2) -> 1 | I9: =MIN(H9,E9)*F9 -> 4600000 | J9: =IF(H9>=E9-0.000001,1,0) -> 1 | K9: =MAX(0,H9-E9)*F9 -> 0 | L9: =SUMIFS(Quantites!$C$2:$C$1166,Quantites!$A$2:$A$1166,A9,Quantites!$B$2:$B$1166,"<="&Dates!$A$3) -> 1 | M9: =MIN(L9,E9)*F9 -> 4600000 | N9: =IF(L9>=E9-0.000001,1,0) -> 1 | O9: =MAX(0,L9-E9)*F9 -> 0 | P9: =SUMIFS(Quantites!$C$2:$C$1166,Quantites!$A$2:$A$1166,A9,Quantites!$B$2:$B$1166,"<="&Dates!$A$4) -> 1 | Q9: =MIN(P9,E9)*F9 -> 4600000 | R9: =IF(P9>=E9-0.000001,1,0) -> 1 | S9: =MAX(0,P9-E9)*F9 -> 0
A10: Q009 | B10: T-01.1.4 | C10: LOT-01 | D10: Massif de fondation de grue | E10: 42 | F10: 145000 | G10: =E10*F10 -> 6090000 | H10: =SUMIFS(Quantites!$C$2:$C$1166,Quantites!$A$2:$A$1166,A10,Quantites!$B$2:$B$1166,"<="&Dates!$A$2) -> 42 | I10: =MIN(H10,E10)*F10 -> 6090000 | J10: =IF(H10>=E10-0.000001,1,0) -> 1 | K10: =MAX(0,H10-E10)*F10 -> 0 | L10: =SUMIFS(Quantites!$C$2:$C$1166,Quantites!$A$2:$A$1166,A10,Quantites!$B$2:$B$1166,"<="&Dates!$A$3) -> 42 | M10: =MIN(L10,E10)*F10 -> 6090000 | N10: =IF(L10>=E10-0.000001,1,0) -> 1 | O10: =MAX(0,L10-E10)*F10 -> 0 | P10: =SUMIFS(Quantites!$C$2:$C$1166,Quantites!$A$2:$A$1166,A10,Quantites!$B$2:$B$1166,"<="&Dates!$A$4) -> 42 | Q10: =MIN(P10,E10)*F10 -> 6090000 | R10: =IF(P10>=E10-0.000001,1,0) -> 1 | S10: =MAX(0,P10-E10)*F10 -> 0
A11: Q010 | B11: T-01.1.4 | C11: LOT-01 | D11: Montage, essais et réception de grue | E11: 1 | F11: 9800000 | G11: =E11*F11 -> 9800000 | H11: =SUMIFS(Quantites!$C$2:$C$1166,Quantites!$A$2:$A$1166,A11,Quantites!$B$2:$B$1166,"<="&Dates!$A$2) -> 1 | I11: =MIN(H11,E11)*F11 -> 9800000 | J11: =IF(H11>=E11-0.000001,1,0) -> 1 | K11: =MAX(0,H11-E11)*F11 -> 0 | L11: =SUMIFS(Quantites!$C$2:$C$1166,Quantites!$A$2:$A$1166,A11,Quantites!$B$2:$B$1166,"<="&Dates!$A$3) -> 1 | M11: =MIN(L11,E11)*F11 -> 9800000 | N11: =IF(L11>=E11-0.000001,1,0) -> 1 | O11: =MAX(0,L11-E11)*F11 -> 0 | P11: =SUMIFS(Quantites!$C$2:$C$1166,Quantites!$A$2:$A$1166,A11,Quantites!$B$2:$B$1166,"<="&Dates!$A$4) -> 1 | Q11: =MIN(P11,E11)*F11 -> 9800000 | R11: =IF(P11>=E11-0.000001,1,0) -> 1 | S11: =MAX(0,P11-E11)*F11 -> 0
A12: Q011 | B12: T-01.1.5 | C12: LOT-01 | D12: Démontage grue et base vie | E12: 1 | F12: 6400000 | G12: =E12*F12 -> 6400000 | H12: =SUMIFS(Quantites!$C$2:$C$1166,Quantites!$A$2:$A$1166,A12,Quantites!$B$2:$B$1166,"<="&Dates!$A$2) -> 0 | I12: =MIN(H12,E12)*F12 -> 0 | J12: =IF(H12>=E12-0.000001,1,0) -> 0 | K12: =MAX(0,H12-E12)*F12 -> 0 | L12: =SUMIFS(Quantites!$C$2:$C$1166,Quantites!$A$2:$A$1166,A12,Quantites!$B$2:$B$1166,"<="&Dates!$A$3) -> 0 | M12: =MIN(L12,E12)*F12 -> 0 | N12: =IF(L12>=E12-0.000001,1,0) -> 0 | O12: =MAX(0,L12-E12)*F12 -> 0 | P12: =SUMIFS(Quantites!$C$2:$C$1166,Quantites!$A$2:$A$1166,A12,Quantites!$B$2:$B$1166,"<="&Dates!$A$4) -> 0 | Q12: =MIN(P12,E12)*F12 -> 0 | R12: =IF(P12>=E12-0.000001,1,0) -> 0 | S12: =MAX(0,P12-E12)*F12 -> 0
A13: Q012 | B13: T-01.1.5 | C13: LOT-01 | D13: Remise en état des abords | E13: 640 | F13: 5500 | G13: =E13*F13 -> 3520000 | H13: =SUMIFS(Quantites!$C$2:$C$1166,Quantites!$A$2:$A$1166,A13,Quantites!$B$2:$B$1166,"<="&Dates!$A$2) -> 0 | I13: =MIN(H13,E13)*F13 -> 0 | J13: =IF(H13>=E13-0.000001,1,0) -> 0 | K13: =MAX(0,H13-E13)*F13 -> 0 | L13: =SUMIFS(Quantites!$C$2:$C$1166,Quantites!$A$2:$A$1166,A13,Quantites!$B$2:$B$1166,"<="&Dates!$A$3) -> 0 | M13: =MIN(L13,E13)*F13 -> 0 | N13: =IF(L13>=E13-0.000001,1,0) -> 0 | O13: =MAX(0,L13-E13)*F13 -> 0 | P13: =SUMIFS(Quantites!$C$2:$C$1166,Quantites!$A$2:$A$1166,A13,Quantites!$B$2:$B$1166,"<="&Dates!$A$4) -> 0 | Q13: =MIN(P13,E13)*F13 -> 0 | R13: =IF(P13>=E13-0.000001,1,0) -> 0 | S13: =MAX(0,P13-E13)*F13 -> 0
... A135: Q134 | B135: T-08.2.3 | C135: LOT-08 | D135: Portillon piéton | E135: 2 | F135: 680000 | G135: =E135*F135 -> 1360000 | H135: =SUMIFS(Quantites!$C$2:$C$1166,Quantites!$A$2:$A$1166,A135,Quantites!$B$2:$B$1166,"<="&Dates!$A$2) -> 0 | I135: =MIN(H135,E135)*F135 -> 0 | J135: =IF(H135>=E135-0.000001,1,0) -> 0 | K135: =MAX(0,H135-E135)*F135 -> 0 | L135: =SUMIFS(Quantites!$C$2:$C$1166,Quantites!$A$2:$A$1166,A135,Quantites!$B$2:$B$1166,"<="&Dates!$A$3) -> 0 | M135: =MIN(L135,E135)*F135 -> 0 | N135: =IF(L135>=E135-0.000001,1,0) -> 0 | O135: =MAX(0,L135-E135)*F135 -> 0 | P135: =SUMIFS(Quantites!$C$2:$C$1166,Quantites!$A$2:$A$1166,A135,Quantites!$B$2:$B$1166,"<="&Dates!$A$4) -> 0 | Q135: =MIN(P135,E135)*F135 -> 0 | R135: =IF(P135>=E135-0.000001,1,0) -> 0 | S135: =MAX(0,P135-E135)*F135 -> 0

Sheet Taches
A1: Tâche | B1: Lot | C1: Méthode | D1: Début prévu | E1: Durée | F1: Budget | G1: Budget arrondi | H1: Jour de début | I1: Avancement au 2026-05-15 | J1: VA au 2026-05-15 | K1: Prévu au 2026-05-15 | L1: VP au 2026-05-15 | M1: Avancement au 2026-07-31 | N1: VA au 2026-07-31 | O1: Prévu au 2026-07-31 | P1: VP au 2026-07-31 | Q1: Avancement au 2026-09-27 | R1: VA au 2026-09-27 | S1: Prévu au 2026-09-27 | T1: VP au 2026-09-27
A2: T-01.1.1 | B2: LOT-01 | C2: UNITES_PHYSIQUES | D2: 46083 | E2: 10 | F2: =SUMIFS(Lignes!$G$2:$G$135,Lignes!$B$2:$B$135,A2) -> 17940000 | G2: =ROUND(F2,0) -> 17940000 | H2: =D2-Parametres!$B$9 -> 0 | I2: =IF(C2="UNITES_PHYSIQUES",IF(F2>0,SUMIFS(Lignes!$I$2:$I$135,Lignes!$B$2:$B$135,A2)/F2,0),IF(C2="JALONS_PONDERES",IF(F2>0,SUMIFS(Lignes!$G$2:$G$135,Lignes!$B$2:$B$135,A2,Lignes!$J$2:$J$135,1)/F2,0),IF(C2="ZERO_CENT",IF(AND(COUNTIFS(Lignes!$B$2:$B$135,A2)>0,COUNTIFS(Lignes!$B$2:$B$135,A2,Lignes!$J$2:$J$135,0)=0),1,0),K2))) -> 1 | J2: =ROUND(MIN(1,MAX(0,I2))*F2,0) -> 17940000 | K2: =IF(Dates!$B$2<H2,0,IF(E2<=0,1,MIN(1,(Dates!$B$2-H2+1)/E2))) -> 1 | L2: =K2*G2 -> 17940000 | M2: =IF(C2="UNITES_PHYSIQUES",IF(F2>0,SUMIFS(Lignes!$M$2:$M$135,Lignes!$B$2:$B$135,A2)/F2,0),IF(C2="JALONS_PONDERES",IF(F2>0,SUMIFS(Lignes!$G$2:$G$135,Lignes!$B$2:$B$135,A2,Lignes!$N$2:$N$135,1)/F2,0),IF(C2="ZERO_CENT",IF(AND(COUNTIFS(Lignes!$B$2:$B$135,A2)>0,COUNTIFS(Lignes!$B$2:$B$135,A2,Lignes!$N$2:$N$135,0)=0),1,0),O2))) -> 1 | N2: =ROUND(MIN(1,MAX(0,M2))*F2,0) -> 17940000 | O2: =IF(Dates!$B$3<H2,0,IF(E2<=0,1,MIN(1,(Dates!$B$3-H2+1)/E2))) -> 1 | P2: =O2*G2 -> 17940000 | Q2: =IF(C2="UNITES_PHYSIQUES",IF(F2>0,SUMIFS(Lignes!$Q$2:$Q$135,Lignes!$B$2:$B$135,A2)/F2,0),IF(C2="JALONS_PONDERES",IF(F2>0,SUMIFS(Lignes!$G$2:$G$135,Lignes!$B$2:$B$135,A2,Lignes!$R$2:$R$135,1)/F2,0),IF(C2="ZERO_CENT",IF(AND(COUNTIFS(Lignes!$B$2:$B$135,A2)>0,COUNTIFS(Lignes!$B$2:$B$135,A2,Lignes!$R$2:$R$135,0)=0),1,0),S2))) -> 1 | R2: =ROUND(MIN(1,MAX(0,Q2))*F2,0) -> 17940000 | S2: =IF(Dates!$B$4<H2,0,IF(E2<=0,1,MIN(1,(Dates!$B$4-H2+1)/E2))) -> 1 | T2: =S2*G2 -> 17940000
A3: T-01.1.2 | B3: LOT-01 | C3: JALONS_PONDERES | D3: 46093 | E3: 12 | F3: =SUMIFS(Lignes!$G$2:$G$135,Lignes!$B$2:$B$135,A3) -> 15560000 | G3: =ROUND(F3,0) -> 15560000 | H3: =D3-Parametres!$B$9 -> 10 | I3: =IF(C3="UNITES_PHYSIQUES",IF(F3>0,SUMIFS(Lignes!$I$2:$I$135,Lignes!$B$2:$B$135,A3)/F3,0),IF(C3="JALONS_PONDERES",IF(F3>0,SUMIFS(Lignes!$G$2:$G$135,Lignes!$B$2:$B$135,A3,Lignes!$J$2:$J$135,1)/F3,0),IF(C3="ZERO_CENT",IF(AND(COUNTIFS(Lignes!$B$2:$B$135,A3)>0,COUNTIFS(Lignes!$B$2:$B$135,A3,Lignes!$J$2:$J$135,0)=0),1,0),K3))) -> 1 | J3: =ROUND(MIN(1,MAX(0,I3))*F3,0) -> 15560000 | K3: =IF(Dates!$B$2<H3,0,IF(E3<=0,1,MIN(1,(Dates!$B$2-H3+1)/E3))) -> 1 | L3: =K3*G3 -> 15560000 | M3: =IF(C3="UNITES_PHYSIQUES",IF(F3>0,SUMIFS(Lignes!$M$2:$M$135,Lignes!$B$2:$B$135,A3)/F3,0),IF(C3="JALONS_PONDERES",IF(F3>0,SUMIFS(Lignes!$G$2:$G$135,Lignes!$B$2:$B$135,A3,Lignes!$N$2:$N$135,1)/F3,0),IF(C3="ZERO_CENT",IF(AND(COUNTIFS(Lignes!$B$2:$B$135,A3)>0,COUNTIFS(Lignes!$B$2:$B$135,A3,Lignes!$N$2:$N$135,0)=0),1,0),O3))) -> 1 | N3: =ROUND(MIN(1,MAX(0,M3))*F3,0) -> 15560000 | O3: =IF(Dates!$B$3<H3,0,IF(E3<=0,1,MIN(1,(Dates!$B$3-H3+1)/E3))) -> 1 | P3: =O3*G3 -> 15560000 | Q3: =IF(C3="UNITES_PHYSIQUES",IF(F3>0,SUMIFS(Lignes!$Q$2:$Q$135,Lignes!$B$2:$B$135,A3)/F3,0),IF(C3="JALONS_PONDERES",IF(F3>0,SUMIFS(Lignes!$G$2:$G$135,Lignes!$B$2:$B$135,A3,Lignes!$R$2:$R$135,1)/F3,0),IF(C3="ZERO_CENT",IF(AND(COUNTIFS(Lignes!$B$2:$B$135,A3)>0,COUNTIFS(Lignes!$B$2:$B$135,A3,Lignes!$R$2:$R$135,0)=0),1,0),S3))) -> 1 | R3: =ROUND(MIN(1,MAX(0,Q3))*F3,0) -> 15560000 | S3: =IF(Dates!$B$4<H3,0,IF(E3<=0,1,MIN(1,(Dates!$B$4-H3+1)/E3))) -> 1 | T3: =S3*G3 -> 15560000
A4: T-01.1.3 | B4: LOT-01 | C4: UNITES_PHYSIQUES | D4: 46105 | E4: 8 | F4: =SUMIFS(Lignes!$G$2:$G$135,Lignes!$B$2:$B$135,A4) -> 6500000 | G4: =ROUND(F4,0) -> 6500000 | H4: =D4-Parametres!$B$9 -> 22 | I4: =IF(C4="UNITES_PHYSIQUES",IF(F4>0,SUMIFS(Lignes!$I$2:$I$135,Lignes!$B$2:$B$135,A4)/F4,0),IF(C4="JALONS_PONDERES",IF(F4>0,SUMIFS(Lignes!$G$2:$G$135,Lignes!$B$2:$B$135,A4,Lignes!$J$2:$J$135,1)/F4,0),IF(C4="ZERO_CENT",IF(AND(COUNTIFS(Lignes!$B$2:$B$135,A4)>0,COUNTIFS(Lignes!$B$2:$B$135,A4,Lignes!$J$2:$J$135,0)=0),1,0),K4))) -> 1 | J4: =ROUND(MIN(1,MAX(0,I4))*F4,0) -> 6500000 | K4: =IF(Dates!$B$2<H4,0,IF(E4<=0,1,MIN(1,(Dates!$B$2-H4+1)/E4))) -> 1 | L4: =K4*G4 -> 6500000 | M4: =IF(C4="UNITES_PHYSIQUES",IF(F4>0,SUMIFS(Lignes!$M$2:$M$135,Lignes!$B$2:$B$135,A4)/F4,0),IF(C4="JALONS_PONDERES",IF(F4>0,SUMIFS(Lignes!$G$2:$G$135,Lignes!$B$2:$B$135,A4,Lignes!$N$2:$N$135,1)/F4,0),IF(C4="ZERO_CENT",IF(AND(COUNTIFS(Lignes!$B$2:$B$135,A4)>0,COUNTIFS(Lignes!$B$2:$B$135,A4,Lignes!$N$2:$N$135,0)=0),1,0),O4))) -> 1 | N4: =ROUND(MIN(1,MAX(0,M4))*F4,0) -> 6500000 | O4: =IF(Dates!$B$3<H4,0,IF(E4<=0,1,MIN(1,(Dates!$B$3-H4+1)/E4))) -> 1 | P4: =O4*G4 -> 6500000 | Q4: =IF(C4="UNITES_PHYSIQUES",IF(F4>0,SUMIFS(Lignes!$Q$2:$Q$135,Lignes!$B$2:$B$135,A4)/F4,0),IF(C4="JALONS_PONDERES",IF(F4>0,SUMIFS(Lignes!$G$2:$G$135,Lignes!$B$2:$B$135,A4,Lignes!$R$2:$R$135,1)/F4,0),IF(C4="ZERO_CENT",IF(AND(COUNTIFS(Lignes!$B$2:$B$135,A4)>0,COUNTIFS(Lignes!$B$2:$B$135,A4,Lignes!$R$2:$R$135,0)=0),1,0),S4))) -> 1 | R4: =ROUND(MIN(1,MAX(0,Q4))*F4,0) -> 6500000 | S4: =IF(Dates!$B$4<H4,0,IF(E4<=0,1,MIN(1,(Dates!$B$4-H4+1)/E4))) -> 1 | T4: =S4*G4 -> 6500000
A5: T-01.1.4 | B5: LOT-01 | C5: ZERO_CENT | D5: 46105 | E5: 6 | F5: =SUMIFS(Lignes!$G$2:$G$135,Lignes!$B$2:$B$135,A5) -> 15890000 | G5: =ROUND(F5,0) -> 15890000 | H5: =D5-Parametres!$B$9 -> 22 | I5: =IF(C5="UNITES_PHYSIQUES",IF(F5>0,SUMIFS(Lignes!$I$2:$I$135,Lignes!$B$2:$B$135,A5)/F5,0),IF(C5="JALONS_PONDERES",IF(F5>0,SUMIFS(Lignes!$G$2:$G$135,Lignes!$B$2:$B$135,A5,Lignes!$J$2:$J$135,1)/F5,0),IF(C5="ZERO_CENT",IF(AND(COUNTIFS(Lignes!$B$2:$B$135,A5)>0,COUNTIFS(Lignes!$B$2:$B$135,A5,Lignes!$J$2:$J$135,0)=0),1,0),K5))) -> 1 | J5: =ROUND(MIN(1,MAX(0,I5))*F5,0) -> 15890000 | K5: =IF(Dates!$B$2<H5,0,IF(E5<=0,1,MIN(1,(Dates!$B$2-H5+1)/E5))) -> 1 | L5: =K5*G5 -> 15890000 | M5: =IF(C5="UNITES_PHYSIQUES",IF(F5>0,SUMIFS(Lignes!$M$2:$M$135,Lignes!$B$2:$B$135,A5)/F5,0),IF(C5="JALONS_PONDERES",IF(F5>0,SUMIFS(Lignes!$G$2:$G$135,Lignes!$B$2:$B$135,A5,Lignes!$N$2:$N$135,1)/F5,0),IF(C5="ZERO_CENT",IF(AND(COUNTIFS(Lignes!$B$2:$B$135,A5)>0,COUNTIFS(Lignes!$B$2:$B$135,A5,Lignes!$N$2:$N$135,0)=0),1,0),O5))) -> 1 | N5: =ROUND(MIN(1,MAX(0,M5))*F5,0) -> 15890000 | O5: =IF(Dates!$B$3<H5,0,IF(E5<=0,1,MIN(1,(Dates!$B$3-H5+1)/E5))) -> 1 | P5: =O5*G5 -> 15890000 | Q5: =IF(C5="UNITES_PHYSIQUES",IF(F5>0,SUMIFS(Lignes!$Q$2:$Q$135,Lignes!$B$2:$B$135,A5)/F5,0),IF(C5="JALONS_PONDERES",IF(F5>0,SUMIFS(Lignes!$G$2:$G$135,Lignes!$B$2:$B$135,A5,Lignes!$R$2:$R$135,1)/F5,0),IF(C5="ZERO_CENT",IF(AND(COUNTIFS(Lignes!$B$2:$B$135,A5)>0,COUNTIFS(Lignes!$B$2:$B$135,A5,Lignes!$R$2:$R$135,0)=0),1,0),S5))) -> 1 | R5: =ROUND(MIN(1,MAX(0,Q5))*F5,0) -> 15890000 | S5: =IF(Dates!$B$4<H5,0,IF(E5<=0,1,MIN(1,(Dates!$B$4-H5+1)/E5))) -> 1 | T5: =S5*G5 -> 15890000
A6: T-01.1.5 | B6: LOT-01 | C6: ZERO_CENT | D6: 46485 | E6: 10 | F6: =SUMIFS(Lignes!$G$2:$G$135,Lignes!$B$2:$B$135,A6) -> 9920000 | G6: =ROUND(F6,0) -> 9920000 | H6: =D6-Parametres!$B$9 -> 402 | I6: =IF(C6="UNITES_PHYSIQUES",IF(F6>0,SUMIFS(Lignes!$I$2:$I$135,Lignes!$B$2:$B$135,A6)/F6,0),IF(C6="JALONS_PONDERES",IF(F6>0,SUMIFS(Lignes!$G$2:$G$135,Lignes!$B$2:$B$135,A6,Lignes!$J$2:$J$135,1)/F6,0),IF(C6="ZERO_CENT",IF(AND(COUNTIFS(Lignes!$B$2:$B$135,A6)>0,COUNTIFS(Lignes!$B$2:$B$135,A6,Lignes!$J$2:$J$135,0)=0),1,0),K6))) -> 0 | J6: =ROUND(MIN(1,MAX(0,I6))*F6,0) -> 0 | K6: =IF(Dates!$B$2<H6,0,IF(E6<=0,1,MIN(1,(Dates!$B$2-H6+1)/E6))) -> 0 | L6: =K6*G6 -> 0 | M6: =IF(C6="UNITES_PHYSIQUES",IF(F6>0,SUMIFS(Lignes!$M$2:$M$135,Lignes!$B$2:$B$135,A6)/F6,0),IF(C6="JALONS_PONDERES",IF(F6>0,SUMIFS(Lignes!$G$2:$G$135,Lignes!$B$2:$B$135,A6,Lignes!$N$2:$N$135,1)/F6,0),IF(C6="ZERO_CENT",IF(AND(COUNTIFS(Lignes!$B$2:$B$135,A6)>0,COUNTIFS(Lignes!$B$2:$B$135,A6,Lignes!$N$2:$N$135,0)=0),1,0),O6))) -> 0 | N6: =ROUND(MIN(1,MAX(0,M6))*F6,0) -> 0 | O6: =IF(Dates!$B$3<H6,0,IF(E6<=0,1,MIN(1,(Dates!$B$3-H6+1)/E6))) -> 0 | P6: =O6*G6 -> 0 | Q6: =IF(C6="UNITES_PHYSIQUES",IF(F6>0,SUMIFS(Lignes!$Q$2:$Q$135,Lignes!$B$2:$B$135,A6)/F6,0),IF(C6="JALONS_PONDERES",IF(F6>0,SUMIFS(Lignes!$G$2:$G$135,Lignes!$B$2:$B$135,A6,Lignes!$R$2:$R$135,1)/F6,0),IF(C6="ZERO_CENT",IF(AND(COUNTIFS(Lignes!$B$2:$B$135,A6)>0,COUNTIFS(Lignes!$B$2:$B$135,A6,Lignes!$R$2:$R$135,0)=0),1,0),S6))) -> 0 | R6: =ROUND(MIN(1,MAX(0,Q6))*F6,0) -> 0 | S6: =IF(Dates!$B$4<H6,0,IF(E6<=0,1,MIN(1,(Dates!$B$4-H6+1)/E6))) -> 0 | T6: =S6*G6 -> 0
A7: T-02.1.1 | B7: LOT-02 | C7: UNITES_PHYSIQUES | D7: 46093 | E7: 8 | F7: =SUMIFS(Lignes!$G$2:$G$135,Lignes!$B$2:$B$135,A7) -> 8256000 | G7: =ROUND(F7,0) -> 8256000 | H7: =D7-Parametres!$B$9 -> 10 | I7: =IF(C7="UNITES_PHYSIQUES",IF(F7>0,SUMIFS(Lignes!$I$2:$I$135,Lignes!$B$2:$B$135,A7)/F7,0),IF(C7="JALONS_PONDERES",IF(F7>0,SUMIFS(Lignes!$G$2:$G$135,Lignes!$B$2:$B$135,A7,Lignes!$J$2:$J$135,1)/F7,0),IF(C7="ZERO_CENT",IF(AND(COUNTIFS(Lignes!$B$2:$B$135,A7)>0,COUNTIFS(Lignes!$B$2:$B$135,A7,Lignes!$J$2:$J$135,0)=0),1,0),K7))) -> 1 | J7: =ROUND(MIN(1,MAX(0,I7))*F7,0) -> 8256000 | K7: =IF(Dates!$B$2<H7,0,IF(E7<=0,1,MIN(1,(Dates!$B$2-H7+1)/E7))) -> 1 | L7: =K7*G7 -> 8256000 | M7: =IF(C7="UNITES_PHYSIQUES",IF(F7>0,SUMIFS(Lignes!$M$2:$M$135,Lignes!$B$2:$B$135,A7)/F7,0),IF(C7="JALONS_PONDERES",IF(F7>0,SUMIFS(Lignes!$G$2:$G$135,Lignes!$B$2:$B$135,A7,Lignes!$N$2:$N$135,1)/F7,0),IF(C7="ZERO_CENT",IF(AND(COUNTIFS(Lignes!$B$2:$B$135,A7)>0,COUNTIFS(Lignes!$B$2:$B$135,A7,Lignes!$N$2:$N$135,0)=0),1,0),O7))) -> 1 | N7: =ROUND(MIN(1,MAX(0,M7))*F7,0) -> 8256000 | O7: =IF(Dates!$B$3<H7,0,IF(E7<=0,1,MIN(1,(Dates!$B$3-H7+1)/E7))) -> 1 | P7: =O7*G7 -> 8256000 | Q7: =IF(C7="UNITES_PHYSIQUES",IF(F7>0,SUMIFS(Lignes!$Q$2:$Q$135,Lignes!$B$2:$B$135,A7)/F7,0),IF(C7="JALONS_PONDERES",IF(F7>0,SUMIFS(Lignes!$G$2:$G$135,Lignes!$B$2:$B$135,A7,Lignes!$R$2:$R$135,1)/F7,0),IF(C7="ZERO_CENT",IF(AND(COUNTIFS(Lignes!$B$2:$B$135,A7)>0,COUNTIFS(Lignes!$B$2:$B$135,A7,Lignes!$R$2:$R$135,0)=0),1,0),S7))) -> 1 | R7: =ROUND(MIN(1,MAX(0,Q7))*F7,0) -> 8256000 | S7: =IF(Dates!$B$4<H7,0,IF(E7<=0,1,MIN(1,(Dates!$B$4-H7+1)/E7))) -> 1 | T7: =S7*G7 -> 8256000
A8: T-02.1.2 | B8: LOT-02 | C8: UNITES_PHYSIQUES | D8: 46101 | E8: 18 | F8: =SUMIFS(Lignes!$G$2:$G$135,Lignes!$B$2:$B$135,A8) -> 31620000 | G8: =ROUND(F8,0) -> 31620000 | H8: =D8-Parametres!$B$9 -> 18 | I8: =IF(C8="UNITES_PHYSIQUES",IF(F8>0,SUMIFS(Lignes!$I$2:$I$135,Lignes!$B$2:$B$135,A8)/F8,0),IF(C8="JALONS_PONDERES",IF(F8>0,SUMIFS(Lignes!$G$2:$G$135,Lignes!$B$2:$B$135,A8,Lignes!$J$2:$J$135,1)/F8,0),IF(C8="ZERO_CENT",IF(AND(COUNTIFS(Lignes!$B$2:$B$135,A8)>0,COUNTIFS(Lignes!$B$2:$B$135,A8,Lignes!$J$2:$J$135,0)=0),1,0),K8))) -> 1 | J8: =ROUND(MIN(1,MAX(0,I8))*F8,0) -> 31620000 | K8: =IF(Dates!$B$2<H8,0,IF(E8<=0,1,MIN(1,(Dates!$B$2-H8+1)/E8))) -> 1 | L8: =K8*G8 -> 31620000 | M8: =IF(C8="UNITES_PHYSIQUES",IF(F8>0,SUMIFS(Lignes!$M$2:$M$135,Lignes!$B$2:$B$135,A8)/F8,0),IF(C8="JALONS_PONDERES",IF(F8>0,SUMIFS(Lignes!$G$2:$G$135,Lignes!$B$2:$B$135,A8,Lignes!$N$2:$N$135,1)/F8,0),IF(C8="ZERO_CENT",IF(AND(COUNTIFS(Lignes!$B$2:$B$135,A8)>0,COUNTIFS(Lignes!$B$2:$B$135,A8,Lignes!$N$2:$N$135,0)=0),1,0),O8))) -> 1 | N8: =ROUND(MIN(1,MAX(0,M8))*F8,0) -> 31620000 | O8: =IF(Dates!$B$3<H8,0,IF(E8<=0,1,MIN(1,(Dates!$B$3-H8+1)/E8))) -> 1 | P8: =O8*G8 -> 31620000 | Q8: =IF(C8="UNITES_PHYSIQUES",IF(F8>0,SUMIFS(Lignes!$Q$2:$Q$135,Lignes!$B$2:$B$135,A8)/F8,0),IF(C8="JALONS_PONDERES",IF(F8>0,SUMIFS(Lignes!$G$2:$G$135,Lignes!$B$2:$B$135,A8,Lignes!$R$2:$R$135,1)/F8,0),IF(C8="ZERO_CENT",IF(AND(COUNTIFS(Lignes!$B$2:$B$135,A8)>0,COUNTIFS(Lignes!$B$2:$B$135,A8,Lignes!$R$2:$R$135,0)=0),1,0),S8))) -> 1 | R8: =ROUND(MIN(1,MAX(0,Q8))*F8,0) -> 31620000 | S8: =IF(Dates!$B$4<H8,0,IF(E8<=0,1,MIN(1,(Dates!$B$4-H8+1)/E8))) -> 1 | T8: =S8*G8 -> 31620000
A9: T-02.1.3 | B9: LOT-02 | C9: UNITES_PHYSIQUES | D9: 46119 | E9: 14 | F9: =SUMIFS(Lignes!$G$2:$G$135,Lignes!$B$2:$B$135,A9) -> 4607400 | G9: =ROUND(F9,0) -> 4607400 | H9: =D9-Parametres!$B$9 -> 36 | I9: =IF(C9="UNITES_PHYSIQUES",IF(F9>0,SUMIFS(Lignes!$I$2:$I$135,Lignes!$B$2:$B$135,A9)/F9,0),IF(C9="JALONS_PONDERES",IF(F9>0,SUMIFS(Lignes!$G$2:$G$135,Lignes!$B$2:$B$135,A9,Lignes!$J$2:$J$135,1)/F9,0),IF(C9="ZERO_CENT",IF(AND(COUNTIFS(Lignes!$B$2:$B$135,A9)>0,COUNTIFS(Lignes!$B$2:$B$135,A9,Lignes!$J$2:$J$135,0)=0),1,0),K9))) -> 1 | J9: =ROUND(MIN(1,MAX(0,I9))*F9,0) -> 4607400 | K9: =IF(Dates!$B$2<H9,0,IF(E9<=0,1,MIN(1,(Dates!$B$2-H9+1)/E9))) -> 1 | L9: =K9*G9 -> 4607400 | M9: =IF(C9="UNITES_PHYSIQUES",IF(F9>0,SUMIFS(Lignes!$M$2:$M$135,Lignes!$B$2:$B$135,A9)/F9,0),IF(C9="JALONS_PONDERES",IF(F9>0,SUMIFS(Lignes!$G$2:$G$135,Lignes!$B$2:$B$135,A9,Lignes!$N$2:$N$135,1)/F9,0),IF(C9="ZERO_CENT",IF(AND(COUNTIFS(Lignes!$B$2:$B$135,A9)>0,COUNTIFS(Lignes!$B$2:$B$135,A9,Lignes!$N$2:$N$135,0)=0),1,0),O9))) -> 1 | N9: =ROUND(MIN(1,MAX(0,M9))*F9,0) -> 4607400 | O9: =IF(Dates!$B$3<H9,0,IF(E9<=0,1,MIN(1,(Dates!$B$3-H9+1)/E9))) -> 1 | P9: =O9*G9 -> 4607400 | Q9: =IF(C9="UNITES_PHYSIQUES",IF(F9>0,SUMIFS(Lignes!$Q$2:$Q$135,Lignes!$B$2:$B$135,A9)/F9,0),IF(C9="JALONS_PONDERES",IF(F9>0,SUMIFS(Lignes!$G$2:$G$135,Lignes!$B$2:$B$135,A9,Lignes!$R$2:$R$135,1)/F9,0),IF(C9="ZERO_CENT",IF(AND(COUNTIFS(Lignes!$B$2:$B$135,A9)>0,COUNTIFS(Lignes!$B$2:$B$135,A9,Lignes!$R$2:$R$135,0)=0),1,0),S9))) -> 1 | R9: =ROUND(MIN(1,MAX(0,Q9))*F9,0) -> 4607400 | S9: =IF(Dates!$B$4<H9,0,IF(E9<=0,1,MIN(1,(Dates!$B$4-H9+1)/E9))) -> 1 | T9: =S9*G9 -> 4607400
A10: T-02.1.4 | B10: LOT-02 | C10: UNITES_PHYSIQUES | D10: 46181 | E10: 12 | F10: =SUMIFS(Lignes!$G$2:$G$135,Lignes!$B$2:$B$135,A10) -> 11580000 | G10: =ROUND(F10,0) -> 11580000 | H10: =D10-Parametres!$B$9 -> 98 | I10: =IF(C10="UNITES_PHYSIQUES",IF(F10>0,SUMIFS(Lignes!$I$2:$I$135,Lignes!$B$2:$B$135,A10)/F10,0),IF(C10="JALONS_PONDERES",IF(F10>0,SUMIFS(Lignes!$G$2:$G$135,Lignes!$B$2:$B$135,A10,Lignes!$J$2:$J$135,1)/F10,0),IF(C10="ZERO_CENT",IF(AND(COUNTIFS(Lignes!$B$2:$B$135,A10)>0,COUNTIFS(Lignes!$B$2:$B$135,A10,Lignes!$J$2:$J$135,0)=0),1,0),K10))) -> 0 | J10: =ROUND(MIN(1,MAX(0,I10))*F10,0) -> 0 | K10: =IF(Dates!$B$2<H10,0,IF(E10<=0,1,MIN(1,(Dates!$B$2-H10+1)/E10))) -> 0 | L10: =K10*G10 -> 0 | M10: =IF(C10="UNITES_PHYSIQUES",IF(F10>0,SUMIFS(Lignes!$M$2:$M$135,Lignes!$B$2:$B$135,A10)/F10,0),IF(C10="JALONS_PONDERES",IF(F10>0,SUMIFS(Lignes!$G$2:$G$135,Lignes!$B$2:$B$135,A10,Lignes!$N$2:$N$135,1)/F10,0),IF(C10="ZERO_CENT",IF(AND(COUNTIFS(Lignes!$B$2:$B$135,A10)>0,COUNTIFS(Lignes!$B$2:$B$135,A10,Lignes!$N$2:$N$135,0)=0),1,0),O10))) -> 1 | N10: =ROUND(MIN(1,MAX(0,M10))*F10,0) -> 11580000 | O10: =IF(Dates!$B$3<H10,0,IF(E10<=0,1,MIN(1,(Dates!$B$3-H10+1)/E10))) -> 1 | P10: =O10*G10 -> 11580000 | Q10: =IF(C10="UNITES_PHYSIQUES",IF(F10>0,SUMIFS(Lignes!$Q$2:$Q$135,Lignes!$B$2:$B$135,A10)/F10,0),IF(C10="JALONS_PONDERES",IF(F10>0,SUMIFS(Lignes!$G$2:$G$135,Lignes!$B$2:$B$135,A10,Lignes!$R$2:$R$135,1)/F10,0),IF(C10="ZERO_CENT",IF(AND(COUNTIFS(Lignes!$B$2:$B$135,A10)>0,COUNTIFS(Lignes!$B$2:$B$135,A10,Lignes!$R$2:$R$135,0)=0),1,0),S10))) -> 1 | R10: =ROUND(MIN(1,MAX(0,Q10))*F10,0) -> 11580000 | S10: =IF(Dates!$B$4<H10,0,IF(E10<=0,1,MIN(1,(Dates!$B$4-H10+1)/E10))) -> 1 | T10: =S10*G10 -> 11580000
A11: T-02.2.1 | B11: LOT-02 | C11: UNITES_PHYSIQUES | D11: 46193 | E11: 15 | F11: =SUMIFS(Lignes!$G$2:$G$135,Lignes!$B$2:$B$135,A11) -> 13083000 | G11: =ROUND(F11,0) -> 13083000 | H11: =D11-Parametres!$B$9 -> 110 | I11: =IF(C11="UNITES_PHYSIQUES",IF(F11>0,SUMIFS(Lignes!$I$2:$I$135,Lignes!$B$2:$B$135,A11)/F11,0),IF(C11="JALONS_PONDERES",IF(F11>0,SUMIFS(Lignes!$G$2:$G$135,Lignes!$B$2:$B$135,A11,Lignes!$J$2:$J$135,1)/F11,0),IF(C11="ZERO_CENT",IF(AND(COUNTIFS(Lignes!$B$2:$B$135,A11)>0,COUNTIFS(Lignes!$B$2:$B$135,A11,Lignes!$J$2:$J$135,0)=0),1,0),K11))) -> 0 | J11: =ROUND(MIN(1,MAX(0,I11))*F11,0) -> 0 | K11: =IF(Dates!$B$2<H11,0,IF(E11<=0,1,MIN(1,(Dates!$B$2-H11+1)/E11))) -> 0 | L11: =K11*G11 -> 0 | M11: =IF(C11="UNITES_PHYSIQUES",IF(F11>0,SUMIFS(Lignes!$M$2:$M$135,Lignes!$B$2:$B$135,A11)/F11,0),IF(C11="JALONS_PONDERES",IF(F11>0,SUMIFS(Lignes!$G$2:$G$135,Lignes!$B$2:$B$135,A11,Lignes!$N$2:$N$135,1)/F11,0),IF(C11="ZERO_CENT",IF(AND(COUNTIFS(Lignes!$B$2:$B$135,A11)>0,COUNTIFS(Lignes!$B$2:$B$135,A11,Lignes!$N$2:$N$135,0)=0),1,0),O11))) -> 1 | N11: =ROUND(MIN(1,MAX(0,M11))*F11,0) -> 13083000 | O11: =IF(Dates!$B$3<H11,0,IF(E11<=0,1,MIN(1,(Dates!$B$3-H11+1)/E11))) -> 1 | P11: =O11*G11 -> 13083000 | Q11: =IF(C11="UNITES_PHYSIQUES",IF(F11>0,SUMIFS(Lignes!$Q$2:$Q$135,Lignes!$B$2:$B$135,A11)/F11,0),IF(C11="JALONS_PONDERES",IF(F11>0,SUMIFS(Lignes!$G$2:$G$135,Lignes!$B$2:$B$135,A11,Lignes!$R$2:$R$135,1)/F11,0),IF(C11="ZERO_CENT",IF(AND(COUNTIFS(Lignes!$B$2:$B$135,A11)>0,COUNTIFS(Lignes!$B$2:$B$135,A11,Lignes!$R$2:$R$135,0)=0),1,0),S11))) -> 1 | R11: =ROUND(MIN(1,MAX(0,Q11))*F11,0) -> 13083000 | S11: =IF(Dates!$B$4<H11,0,IF(E11<=0,1,MIN(1,(Dates!$B$4-H11+1)/E11))) -> 1 | T11: =S11*G11 -> 13083000
A12: T-02.2.2 | B12: LOT-02 | C12: UNITES_PHYSIQUES | D12: 46208 | E12: 12 | F12: =SUMIFS(Lignes!$G$2:$G$135,Lignes!$B$2:$B$135,A12) -> 11124000 | G12: =ROUND(F12,0) -> 11124000 | H12: =D12-Parametres!$B$9 -> 125 | I12: =IF(C12="UNITES_PHYSIQUES",IF(F12>0,SUMIFS(Lignes!$I$2:$I$135,Lignes!$B$2:$B$135,A12)/F12,0),IF(C12="JALONS_PONDERES",IF(F12>0,SUMIFS(Lignes!$G$2:$G$135,Lignes!$B$2:$B$135,A12,Lignes!$J$2:$J$135,1)/F12,0),IF(C12="ZERO_CENT",IF(AND(COUNTIFS(Lignes!$B$2:$B$135,A12)>0,COUNTIFS(Lignes!$B$2:$B$135,A12,Lignes!$J$2:$J$135,0)=0),1,0),K12))) -> 0 | J12: =ROUND(MIN(1,MAX(0,I12))*F12,0) -> 0 | K12: =IF(Dates!$B$2<H12,0,IF(E12<=0,1,MIN(1,(Dates!$B$2-H12+1)/E12))) -> 0 | L12: =K12*G12 -> 0 | M12: =IF(C12="UNITES_PHYSIQUES",IF(F12>0,SUMIFS(Lignes!$M$2:$M$135,Lignes!$B$2:$B$135,A12)/F12,0),IF(C12="JALONS_PONDERES",IF(F12>0,SUMIFS(Lignes!$G$2:$G$135,Lignes!$B$2:$B$135,A12,Lignes!$N$2:$N$135,1)/F12,0),IF(C12="ZERO_CENT",IF(AND(COUNTIFS(Lignes!$B$2:$B$135,A12)>0,COUNTIFS(Lignes!$B$2:$B$135,A12,Lignes!$N$2:$N$135,0)=0),1,0),O12))) -> 0.9305 | N12: =ROUND(MIN(1,MAX(0,M12))*F12,0) -> 10350882 | O12: =IF(Dates!$B$3<H12,0,IF(E12<=0,1,MIN(1,(Dates!$B$3-H12+1)/E12))) -> 1 | P12: =O12*G12 -> 11124000 | Q12: =IF(C12="UNITES_PHYSIQUES",IF(F12>0,SUMIFS(Lignes!$Q$2:$Q$135,Lignes!$B$2:$B$135,A12)/F12,0),IF(C12="JALONS_PONDERES",IF(F12>0,SUMIFS(Lignes!$G$2:$G$135,Lignes!$B$2:$B$135,A12,Lignes!$R$2:$R$135,1)/F12,0),IF(C12="ZERO_CENT",IF(AND(COUNTIFS(Lignes!$B$2:$B$135,A12)>0,COUNTIFS(Lignes!$B$2:$B$135,A12,Lignes!$R$2:$R$135,0)=0),1,0),S12))) -> 1 | R12: =ROUND(MIN(1,MAX(0,Q12))*F12,0) -> 11124000 | S12: =IF(Dates!$B$4<H12,0,IF(E12<=0,1,MIN(1,(Dates!$B$4-H12+1)/E12))) -> 1 | T12: =S12*G12 -> 11124000
A13: T-02.2.3 | B13: LOT-02 | C13: UNITES_PHYSIQUES | D13: 46203 | E13: 10 | F13: =SUMIFS(Lignes!$G$2:$G$135,Lignes!$B$2:$B$135,A13) -> 3936000 | G13: =ROUND(F13,0) -> 3936000 | H13: =D13-Parametres!$B$9 -> 120 | I13: =IF(C13="UNITES_PHYSIQUES",IF(F13>0,SUMIFS(Lignes!$I$2:$I$135,Lignes!$B$2:$B$135,A13)/F13,0),IF(C13="JALONS_PONDERES",IF(F13>0,SUMIFS(Lignes!$G$2:$G$135,Lignes!$B$2:$B$135,A13,Lignes!$J$2:$J$135,1)/F13,0),IF(C13="ZERO_CENT",IF(AND(COUNTIFS(Lignes!$B$2:$B$135,A13)>0,COUNTIFS(Lignes!$B$2:$B$135,A13,Lignes!$J$2:$J$135,0)=0),1,0),K13))) -> 0 | J13: =ROUND(MIN(1,MAX(0,I13))*F13,0) -> 0 | K13: =IF(Dates!$B$2<H13,0,IF(E13<=0,1,MIN(1,(Dates!$B$2-H13+1)/E13))) -> 0 | L13: =K13*G13 -> 0 | M13: =IF(C13="UNITES_PHYSIQUES",IF(F13>0,SUMIFS(Lignes!$M$2:$M$135,Lignes!$B$2:$B$135,A13)/F13,0),IF(C13="JALONS_PONDERES",IF(F13>0,SUMIFS(Lignes!$G$2:$G$135,Lignes!$B$2:$B$135,A13,Lignes!$N$2:$N$135,1)/F13,0),IF(C13="ZERO_CENT",IF(AND(COUNTIFS(Lignes!$B$2:$B$135,A13)>0,COUNTIFS(Lignes!$B$2:$B$135,A13,Lignes!$N$2:$N$135,0)=0),1,0),O13))) -> 1 | N13: =ROUND(MIN(1,MAX(0,M13))*F13,0) -> 3936000 | O13: =IF(Dates!$B$3<H13,0,IF(E13<=0,1,MIN(1,(Dates!$B$3-H13+1)/E13))) -> 1 | P13: =O13*G13 -> 3936000 | Q13: =IF(C13="UNITES_PHYSIQUES",IF(F13>0,SUMIFS(Lignes!$Q$2:$Q$135,Lignes!$B$2:$B$135,A13)/F13,0),IF(C13="JALONS_PONDERES",IF(F13>0,SUMIFS(Lignes!$G$2:$G$135,Lignes!$B$2:$B$135,A13,Lignes!$R$2:$R$135,1)/F13,0),IF(C13="ZERO_CENT",IF(AND(COUNTIFS(Lignes!$B$2:$B$135,A13)>0,COUNTIFS(Lignes!$B$2:$B$135,A13,Lignes!$R$2:$R$135,0)=0),1,0),S13))) -> 1 | R13: =ROUND(MIN(1,MAX(0,Q13))*F13,0) -> 3936000 | S13: =IF(Dates!$B$4<H13,0,IF(E13<=0,1,MIN(1,(Dates!$B$4-H13+1)/E13))) -> 1 | T13: =S13*G13 -> 3936000
... A60: T-08.2.3 | B60: LOT-08 | C60: UNITES_PHYSIQUES | D60: 46467 | E60: 18 | F60: =SUMIFS(Lignes!$G$2:$G$135,Lignes!$B$2:$B$135,A60) -> 21680000 | G60: =ROUND(F60,0) -> 21680000 | H60: =D60-Parametres!$B$9 -> 384 | I60: =IF(C60="UNITES_PHYSIQUES",IF(F60>0,SUMIFS(Lignes!$I$2:$I$135,Lignes!$B$2:$B$135,A60)/F60,0),IF(C60="JALONS_PONDERES",IF(F60>0,SUMIFS(Lignes!$G$2:$G$135,Lignes!$B$2:$B$135,A60,Lignes!$J$2:$J$135,1)/F60,0),IF(C60="ZERO_CENT",IF(AND(COUNTIFS(Lignes!$B$2:$B$135,A60)>0,COUNTIFS(Lignes!$B$2:$B$135,A60,Lignes!$J$2:$J$135,0)=0),1,0),K60))) -> 0 | J60: =ROUND(MIN(1,MAX(0,I60))*F60,0) -> 0 | K60: =IF(Dates!$B$2<H60,0,IF(E60<=0,1,MIN(1,(Dates!$B$2-H60+1)/E60))) -> 0 | L60: =K60*G60 -> 0 | M60: =IF(C60="UNITES_PHYSIQUES",IF(F60>0,SUMIFS(Lignes!$M$2:$M$135,Lignes!$B$2:$B$135,A60)/F60,0),IF(C60="JALONS_PONDERES",IF(F60>0,SUMIFS(Lignes!$G$2:$G$135,Lignes!$B$2:$B$135,A60,Lignes!$N$2:$N$135,1)/F60,0),IF(C60="ZERO_CENT",IF(AND(COUNTIFS(Lignes!$B$2:$B$135,A60)>0,COUNTIFS(Lignes!$B$2:$B$135,A60,Lignes!$N$2:$N$135,0)=0),1,0),O60))) -> 0 | N60: =ROUND(MIN(1,MAX(0,M60))*F60,0) -> 0 | O60: =IF(Dates!$B$3<H60,0,IF(E60<=0,1,MIN(1,(Dates!$B$3-H60+1)/E60))) -> 0 | P60: =O60*G60 -> 0 | Q60: =IF(C60="UNITES_PHYSIQUES",IF(F60>0,SUMIFS(Lignes!$Q$2:$Q$135,Lignes!$B$2:$B$135,A60)/F60,0),IF(C60="JALONS_PONDERES",IF(F60>0,SUMIFS(Lignes!$G$2:$G$135,Lignes!$B$2:$B$135,A60,Lignes!$R$2:$R$135,1)/F60,0),IF(C60="ZERO_CENT",IF(AND(COUNTIFS(Lignes!$B$2:$B$135,A60)>0,COUNTIFS(Lignes!$B$2:$B$135,A60,Lignes!$R$2:$R$135,0)=0),1,0),S60))) -> 0 | R60: =ROUND(MIN(1,MAX(0,Q60))*F60,0) -> 0 | S60: =IF(Dates!$B$4<H60,0,IF(E60<=0,1,MIN(1,(Dates!$B$4-H60+1)/E60))) -> 0 | T60: =S60*G60 -> 0

Sheet Debourse
A1: Date | B1: Ouvriers LOT-01 | C1: Encadrants LOT-01 | D1: Ouvriers LOT-02 | E1: Encadrants LOT-02 | F1: Ouvriers LOT-03 | G1: Encadrants LOT-03 | H1: Ouvriers LOT-04 | I1: Encadrants LOT-04 | J1: Ouvriers LOT-05 | K1: Encadrants LOT-05 | L1: Ouvriers LOT-06 | M1: Encadrants LOT-06 | N1: Ouvriers LOT-07 | O1: Encadrants LOT-07 | P1: Ouvriers LOT-08 | Q1: Encadrants LOT-08
A2: 46083 | B2: =SUMIFS(Equipes!$D$2:$D$60,Equipes!$A$2:$A$60,"LOT-01",Equipes!$B$2:$B$60,"<="&$A2,Equipes!$C$2:$C$60,">="&$A2) -> 5 | C2: =IF(B2>0,ROUNDUP(B2/Parametres!$B$7,0)+1,0) -> 2 | D2: =SUMIFS(Equipes!$D$2:$D$60,Equipes!$A$2:$A$60,"LOT-02",Equipes!$B$2:$B$60,"<="&$A2,Equipes!$C$2:$C$60,">="&$A2) -> 0 | E2: =IF(D2>0,ROUNDUP(D2/Parametres!$B$7,0)+1,0) -> 0 | F2: =SUMIFS(Equipes!$D$2:$D$60,Equipes!$A$2:$A$60,"LOT-03",Equipes!$B$2:$B$60,"<="&$A2,Equipes!$C$2:$C$60,">="&$A2) -> 0 | G2: =IF(F2>0,ROUNDUP(F2/Parametres!$B$7,0)+1,0) -> 0 | H2: =SUMIFS(Equipes!$D$2:$D$60,Equipes!$A$2:$A$60,"LOT-04",Equipes!$B$2:$B$60,"<="&$A2,Equipes!$C$2:$C$60,">="&$A2) -> 0 | I2: =IF(H2>0,ROUNDUP(H2/Parametres!$B$7,0)+1,0) -> 0 | J2: =SUMIFS(Equipes!$D$2:$D$60,Equipes!$A$2:$A$60,"LOT-05",Equipes!$B$2:$B$60,"<="&$A2,Equipes!$C$2:$C$60,">="&$A2) -> 0 | K2: =IF(J2>0,ROUNDUP(J2/Parametres!$B$7,0)+1,0) -> 0 | L2: =SUMIFS(Equipes!$D$2:$D$60,Equipes!$A$2:$A$60,"LOT-06",Equipes!$B$2:$B$60,"<="&$A2,Equipes!$C$2:$C$60,">="&$A2) -> 0 | M2: =IF(L2>0,ROUNDUP(L2/Parametres!$B$7,0)+1,0) -> 0 | N2: =SUMIFS(Equipes!$D$2:$D$60,Equipes!$A$2:$A$60,"LOT-07",Equipes!$B$2:$B$60,"<="&$A2,Equipes!$C$2:$C$60,">="&$A2) -> 0 | O2: =IF(N2>0,ROUNDUP(N2/Parametres!$B$7,0)+1,0) -> 0 | P2: =SUMIFS(Equipes!$D$2:$D$60,Equipes!$A$2:$A$60,"LOT-08",Equipes!$B$2:$B$60,"<="&$A2,Equipes!$C$2:$C$60,">="&$A2) -> 0 | Q2: =IF(P2>0,ROUNDUP(P2/Parametres!$B$7,0)+1,0) -> 0
A3: 46084 | B3: =SUMIFS(Equipes!$D$2:$D$60,Equipes!$A$2:$A$60,"LOT-01",Equipes!$B$2:$B$60,"<="&$A3,Equipes!$C$2:$C$60,">="&$A3) -> 5 | C3: =IF(B3>0,ROUNDUP(B3/Parametres!$B$7,0)+1,0) -> 2 | D3: =SUMIFS(Equipes!$D$2:$D$60,Equipes!$A$2:$A$60,"LOT-02",Equipes!$B$2:$B$60,"<="&$A3,Equipes!$C$2:$C$60,">="&$A3) -> 0 | E3: =IF(D3>0,ROUNDUP(D3/Parametres!$B$7,0)+1,0) -> 0 | F3: =SUMIFS(Equipes!$D$2:$D$60,Equipes!$A$2:$A$60,"LOT-03",Equipes!$B$2:$B$60,"<="&$A3,Equipes!$C$2:$C$60,">="&$A3) -> 0 | G3: =IF(F3>0,ROUNDUP(F3/Parametres!$B$7,0)+1,0) -> 0 | H3: =SUMIFS(Equipes!$D$2:$D$60,Equipes!$A$2:$A$60,"LOT-04",Equipes!$B$2:$B$60,"<="&$A3,Equipes!$C$2:$C$60,">="&$A3) -> 0 | I3: =IF(H3>0,ROUNDUP(H3/Parametres!$B$7,0)+1,0) -> 0 | J3: =SUMIFS(Equipes!$D$2:$D$60,Equipes!$A$2:$A$60,"LOT-05",Equipes!$B$2:$B$60,"<="&$A3,Equipes!$C$2:$C$60,">="&$A3) -> 0 | K3: =IF(J3>0,ROUNDUP(J3/Parametres!$B$7,0)+1,0) -> 0 | L3: =SUMIFS(Equipes!$D$2:$D$60,Equipes!$A$2:$A$60,"LOT-06",Equipes!$B$2:$B$60,"<="&$A3,Equipes!$C$2:$C$60,">="&$A3) -> 0 | M3: =IF(L3>0,ROUNDUP(L3/Parametres!$B$7,0)+1,0) -> 0 | N3: =SUMIFS(Equipes!$D$2:$D$60,Equipes!$A$2:$A$60,"LOT-07",Equipes!$B$2:$B$60,"<="&$A3,Equipes!$C$2:$C$60,">="&$A3) -> 0 | O3: =IF(N3>0,ROUNDUP(N3/Parametres!$B$7,0)+1,0) -> 0 | P3: =SUMIFS(Equipes!$D$2:$D$60,Equipes!$A$2:$A$60,"LOT-08",Equipes!$B$2:$B$60,"<="&$A3,Equipes!$C$2:$C$60,">="&$A3) -> 0 | Q3: =IF(P3>0,ROUNDUP(P3/Parametres!$B$7,0)+1,0) -> 0
A4: 46085 | B4: =SUMIFS(Equipes!$D$2:$D$60,Equipes!$A$2:$A$60,"LOT-01",Equipes!$B$2:$B$60,"<="&$A4,Equipes!$C$2:$C$60,">="&$A4) -> 5 | C4: =IF(B4>0,ROUNDUP(B4/Parametres!$B$7,0)+1,0) -> 2 | D4: =SUMIFS(Equipes!$D$2:$D$60,Equipes!$A$2:$A$60,"LOT-02",Equipes!$B$2:$B$60,"<="&$A4,Equipes!$C$2:$C$60,">="&$A4) -> 0 | E4: =IF(D4>0,ROUNDUP(D4/Parametres!$B$7,0)+1,0) -> 0 | F4: =SUMIFS(Equipes!$D$2:$D$60,Equipes!$A$2:$A$60,"LOT-03",Equipes!$B$2:$B$60,"<="&$A4,Equipes!$C$2:$C$60,">="&$A4) -> 0 | G4: =IF(F4>0,ROUNDUP(F4/Parametres!$B$7,0)+1,0) -> 0 | H4: =SUMIFS(Equipes!$D$2:$D$60,Equipes!$A$2:$A$60,"LOT-04",Equipes!$B$2:$B$60,"<="&$A4,Equipes!$C$2:$C$60,">="&$A4) -> 0 | I4: =IF(H4>0,ROUNDUP(H4/Parametres!$B$7,0)+1,0) -> 0 | J4: =SUMIFS(Equipes!$D$2:$D$60,Equipes!$A$2:$A$60,"LOT-05",Equipes!$B$2:$B$60,"<="&$A4,Equipes!$C$2:$C$60,">="&$A4) -> 0 | K4: =IF(J4>0,ROUNDUP(J4/Parametres!$B$7,0)+1,0) -> 0 | L4: =SUMIFS(Equipes!$D$2:$D$60,Equipes!$A$2:$A$60,"LOT-06",Equipes!$B$2:$B$60,"<="&$A4,Equipes!$C$2:$C$60,">="&$A4) -> 0 | M4: =IF(L4>0,ROUNDUP(L4/Parametres!$B$7,0)+1,0) -> 0 | N4: =SUMIFS(Equipes!$D$2:$D$60,Equipes!$A$2:$A$60,"LOT-07",Equipes!$B$2:$B$60,"<="&$A4,Equipes!$C$2:$C$60,">="&$A4) -> 0 | O4: =IF(N4>0,ROUNDUP(N4/Parametres!$B$7,0)+1,0) -> 0 | P4: =SUMIFS(Equipes!$D$2:$D$60,Equipes!$A$2:$A$60,"LOT-08",Equipes!$B$2:$B$60,"<="&$A4,Equipes!$C$2:$C$60,">="&$A4) -> 0 | Q4: =IF(P4>0,ROUNDUP(P4/Parametres!$B$7,0)+1,0) -> 0
A5: 46086 | B5: =SUMIFS(Equipes!$D$2:$D$60,Equipes!$A$2:$A$60,"LOT-01",Equipes!$B$2:$B$60,"<="&$A5,Equipes!$C$2:$C$60,">="&$A5) -> 5 | C5: =IF(B5>0,ROUNDUP(B5/Parametres!$B$7,0)+1,0) -> 2 | D5: =SUMIFS(Equipes!$D$2:$D$60,Equipes!$A$2:$A$60,"LOT-02",Equipes!$B$2:$B$60,"<="&$A5,Equipes!$C$2:$C$60,">="&$A5) -> 0 | E5: =IF(D5>0,ROUNDUP(D5/Parametres!$B$7,0)+1,0) -> 0 | F5: =SUMIFS(Equipes!$D$2:$D$60,Equipes!$A$2:$A$60,"LOT-03",Equipes!$B$2:$B$60,"<="&$A5,Equipes!$C$2:$C$60,">="&$A5) -> 0 | G5: =IF(F5>0,ROUNDUP(F5/Parametres!$B$7,0)+1,0) -> 0 | H5: =SUMIFS(Equipes!$D$2:$D$60,Equipes!$A$2:$A$60,"LOT-04",Equipes!$B$2:$B$60,"<="&$A5,Equipes!$C$2:$C$60,">="&$A5) -> 0 | I5: =IF(H5>0,ROUNDUP(H5/Parametres!$B$7,0)+1,0) -> 0 | J5: =SUMIFS(Equipes!$D$2:$D$60,Equipes!$A$2:$A$60,"LOT-05",Equipes!$B$2:$B$60,"<="&$A5,Equipes!$C$2:$C$60,">="&$A5) -> 0 | K5: =IF(J5>0,ROUNDUP(J5/Parametres!$B$7,0)+1,0) -> 0 | L5: =SUMIFS(Equipes!$D$2:$D$60,Equipes!$A$2:$A$60,"LOT-06",Equipes!$B$2:$B$60,"<="&$A5,Equipes!$C$2:$C$60,">="&$A5) -> 0 | M5: =IF(L5>0,ROUNDUP(L5/Parametres!$B$7,0)+1,0) -> 0 | N5: =SUMIFS(Equipes!$D$2:$D$60,Equipes!$A$2:$A$60,"LOT-07",Equipes!$B$2:$B$60,"<="&$A5,Equipes!$C$2:$C$60,">="&$A5) -> 0 | O5: =IF(N5>0,ROUNDUP(N5/Parametres!$B$7,0)+1,0) -> 0 | P5: =SUMIFS(Equipes!$D$2:$D$60,Equipes!$A$2:$A$60,"LOT-08",Equipes!$B$2:$B$60,"<="&$A5,Equipes!$C$2:$C$60,">="&$A5) -> 0 | Q5: =IF(P5>0,ROUNDUP(P5/Parametres!$B$7,0)+1,0) -> 0
A6: 46087 | B6: =SUMIFS(Equipes!$D$2:$D$60,Equipes!$A$2:$A$60,"LOT-01",Equipes!$B$2:$B$60,"<="&$A6,Equipes!$C$2:$C$60,">="&$A6) -> 5 | C6: =IF(B6>0,ROUNDUP(B6/Parametres!$B$7,0)+1,0) -> 2 | D6: =SUMIFS(Equipes!$D$2:$D$60,Equipes!$A$2:$A$60,"LOT-02",Equipes!$B$2:$B$60,"<="&$A6,Equipes!$C$2:$C$60,">="&$A6) -> 0 | E6: =IF(D6>0,ROUNDUP(D6/Parametres!$B$7,0)+1,0) -> 0 | F6: =SUMIFS(Equipes!$D$2:$D$60,Equipes!$A$2:$A$60,"LOT-03",Equipes!$B$2:$B$60,"<="&$A6,Equipes!$C$2:$C$60,">="&$A6) -> 0 | G6: =IF(F6>0,ROUNDUP(F6/Parametres!$B$7,0)+1,0) -> 0 | H6: =SUMIFS(Equipes!$D$2:$D$60,Equipes!$A$2:$A$60,"LOT-04",Equipes!$B$2:$B$60,"<="&$A6,Equipes!$C$2:$C$60,">="&$A6) -> 0 | I6: =IF(H6>0,ROUNDUP(H6/Parametres!$B$7,0)+1,0) -> 0 | J6: =SUMIFS(Equipes!$D$2:$D$60,Equipes!$A$2:$A$60,"LOT-05",Equipes!$B$2:$B$60,"<="&$A6,Equipes!$C$2:$C$60,">="&$A6) -> 0 | K6: =IF(J6>0,ROUNDUP(J6/Parametres!$B$7,0)+1,0) -> 0 | L6: =SUMIFS(Equipes!$D$2:$D$60,Equipes!$A$2:$A$60,"LOT-06",Equipes!$B$2:$B$60,"<="&$A6,Equipes!$C$2:$C$60,">="&$A6) -> 0 | M6: =IF(L6>0,ROUNDUP(L6/Parametres!$B$7,0)+1,0) -> 0 | N6: =SUMIFS(Equipes!$D$2:$D$60,Equipes!$A$2:$A$60,"LOT-07",Equipes!$B$2:$B$60,"<="&$A6,Equipes!$C$2:$C$60,">="&$A6) -> 0 | O6: =IF(N6>0,ROUNDUP(N6/Parametres!$B$7,0)+1,0) -> 0 | P6: =SUMIFS(Equipes!$D$2:$D$60,Equipes!$A$2:$A$60,"LOT-08",Equipes!$B$2:$B$60,"<="&$A6,Equipes!$C$2:$C$60,">="&$A6) -> 0 | Q6: =IF(P6>0,ROUNDUP(P6/Parametres!$B$7,0)+1,0) -> 0
A7: 46088 | B7: =SUMIFS(Equipes!$D$2:$D$60,Equipes!$A$2:$A$60,"LOT-01",Equipes!$B$2:$B$60,"<="&$A7,Equipes!$C$2:$C$60,">="&$A7) -> 5 | C7: =IF(B7>0,ROUNDUP(B7/Parametres!$B$7,0)+1,0) -> 2 | D7: =SUMIFS(Equipes!$D$2:$D$60,Equipes!$A$2:$A$60,"LOT-02",Equipes!$B$2:$B$60,"<="&$A7,Equipes!$C$2:$C$60,">="&$A7) -> 0 | E7: =IF(D7>0,ROUNDUP(D7/Parametres!$B$7,0)+1,0) -> 0 | F7: =SUMIFS(Equipes!$D$2:$D$60,Equipes!$A$2:$A$60,"LOT-03",Equipes!$B$2:$B$60,"<="&$A7,Equipes!$C$2:$C$60,">="&$A7) -> 0 | G7: =IF(F7>0,ROUNDUP(F7/Parametres!$B$7,0)+1,0) -> 0 | H7: =SUMIFS(Equipes!$D$2:$D$60,Equipes!$A$2:$A$60,"LOT-04",Equipes!$B$2:$B$60,"<="&$A7,Equipes!$C$2:$C$60,">="&$A7) -> 0 | I7: =IF(H7>0,ROUNDUP(H7/Parametres!$B$7,0)+1,0) -> 0 | J7: =SUMIFS(Equipes!$D$2:$D$60,Equipes!$A$2:$A$60,"LOT-05",Equipes!$B$2:$B$60,"<="&$A7,Equipes!$C$2:$C$60,">="&$A7) -> 0 | K7: =IF(J7>0,ROUNDUP(J7/Parametres!$B$7,0)+1,0) -> 0 | L7: =SUMIFS(Equipes!$D$2:$D$60,Equipes!$A$2:$A$60,"LOT-06",Equipes!$B$2:$B$60,"<="&$A7,Equipes!$C$2:$C$60,">="&$A7) -> 0 | M7: =IF(L7>0,ROUNDUP(L7/Parametres!$B$7,0)+1,0) -> 0 | N7: =SUMIFS(Equipes!$D$2:$D$60,Equipes!$A$2:$A$60,"LOT-07",Equipes!$B$2:$B$60,"<="&$A7,Equipes!$C$2:$C$60,">="&$A7) -> 0 | O7: =IF(N7>0,ROUNDUP(N7/Parametres!$B$7,0)+1,0) -> 0 | P7: =SUMIFS(Equipes!$D$2:$D$60,Equipes!$A$2:$A$60,"LOT-08",Equipes!$B$2:$B$60,"<="&$A7,Equipes!$C$2:$C$60,">="&$A7) -> 0 | Q7: =IF(P7>0,ROUNDUP(P7/Parametres!$B$7,0)+1,0) -> 0
A8: 46089 | B8: =SUMIFS(Equipes!$D$2:$D$60,Equipes!$A$2:$A$60,"LOT-01",Equipes!$B$2:$B$60,"<="&$A8,Equipes!$C$2:$C$60,">="&$A8) -> 5 | C8: =IF(B8>0,ROUNDUP(B8/Parametres!$B$7,0)+1,0) -> 2 | D8: =SUMIFS(Equipes!$D$2:$D$60,Equipes!$A$2:$A$60,"LOT-02",Equipes!$B$2:$B$60,"<="&$A8,Equipes!$C$2:$C$60,">="&$A8) -> 0 | E8: =IF(D8>0,ROUNDUP(D8/Parametres!$B$7,0)+1,0) -> 0 | F8: =SUMIFS(Equipes!$D$2:$D$60,Equipes!$A$2:$A$60,"LOT-03",Equipes!$B$2:$B$60,"<="&$A8,Equipes!$C$2:$C$60,">="&$A8) -> 0 | G8: =IF(F8>0,ROUNDUP(F8/Parametres!$B$7,0)+1,0) -> 0 | H8: =SUMIFS(Equipes!$D$2:$D$60,Equipes!$A$2:$A$60,"LOT-04",Equipes!$B$2:$B$60,"<="&$A8,Equipes!$C$2:$C$60,">="&$A8) -> 0 | I8: =IF(H8>0,ROUNDUP(H8/Parametres!$B$7,0)+1,0) -> 0 | J8: =SUMIFS(Equipes!$D$2:$D$60,Equipes!$A$2:$A$60,"LOT-05",Equipes!$B$2:$B$60,"<="&$A8,Equipes!$C$2:$C$60,">="&$A8) -> 0 | K8: =IF(J8>0,ROUNDUP(J8/Parametres!$B$7,0)+1,0) -> 0 | L8: =SUMIFS(Equipes!$D$2:$D$60,Equipes!$A$2:$A$60,"LOT-06",Equipes!$B$2:$B$60,"<="&$A8,Equipes!$C$2:$C$60,">="&$A8) -> 0 | M8: =IF(L8>0,ROUNDUP(L8/Parametres!$B$7,0)+1,0) -> 0 | N8: =SUMIFS(Equipes!$D$2:$D$60,Equipes!$A$2:$A$60,"LOT-07",Equipes!$B$2:$B$60,"<="&$A8,Equipes!$C$2:$C$60,">="&$A8) -> 0 | O8: =IF(N8>0,ROUNDUP(N8/Parametres!$B$7,0)+1,0) -> 0 | P8: =SUMIFS(Equipes!$D$2:$D$60,Equipes!$A$2:$A$60,"LOT-08",Equipes!$B$2:$B$60,"<="&$A8,Equipes!$C$2:$C$60,">="&$A8) -> 0 | Q8: =IF(P8>0,ROUNDUP(P8/Parametres!$B$7,0)+1,0) -> 0
A9: 46090 | B9: =SUMIFS(Equipes!$D$2:$D$60,Equipes!$A$2:$A$60,"LOT-01",Equipes!$B$2:$B$60,"<="&$A9,Equipes!$C$2:$C$60,">="&$A9) -> 5 | C9: =IF(B9>0,ROUNDUP(B9/Parametres!$B$7,0)+1,0) -> 2 | D9: =SUMIFS(Equipes!$D$2:$D$60,Equipes!$A$2:$A$60,"LOT-02",Equipes!$B$2:$B$60,"<="&$A9,Equipes!$C$2:$C$60,">="&$A9) -> 0 | E9: =IF(D9>0,ROUNDUP(D9/Parametres!$B$7,0)+1,0) -> 0 | F9: =SUMIFS(Equipes!$D$2:$D$60,Equipes!$A$2:$A$60,"LOT-03",Equipes!$B$2:$B$60,"<="&$A9,Equipes!$C$2:$C$60,">="&$A9) -> 0 | G9: =IF(F9>0,ROUNDUP(F9/Parametres!$B$7,0)+1,0) -> 0 | H9: =SUMIFS(Equipes!$D$2:$D$60,Equipes!$A$2:$A$60,"LOT-04",Equipes!$B$2:$B$60,"<="&$A9,Equipes!$C$2:$C$60,">="&$A9) -> 0 | I9: =IF(H9>0,ROUNDUP(H9/Parametres!$B$7,0)+1,0) -> 0 | J9: =SUMIFS(Equipes!$D$2:$D$60,Equipes!$A$2:$A$60,"LOT-05",Equipes!$B$2:$B$60,"<="&$A9,Equipes!$C$2:$C$60,">="&$A9) -> 0 | K9: =IF(J9>0,ROUNDUP(J9/Parametres!$B$7,0)+1,0) -> 0 | L9: =SUMIFS(Equipes!$D$2:$D$60,Equipes!$A$2:$A$60,"LOT-06",Equipes!$B$2:$B$60,"<="&$A9,Equipes!$C$2:$C$60,">="&$A9) -> 0 | M9: =IF(L9>0,ROUNDUP(L9/Parametres!$B$7,0)+1,0) -> 0 | N9: =SUMIFS(Equipes!$D$2:$D$60,Equipes!$A$2:$A$60,"LOT-07",Equipes!$B$2:$B$60,"<="&$A9,Equipes!$C$2:$C$60,">="&$A9) -> 0 | O9: =IF(N9>0,ROUNDUP(N9/Parametres!$B$7,0)+1,0) -> 0 | P9: =SUMIFS(Equipes!$D$2:$D$60,Equipes!$A$2:$A$60,"LOT-08",Equipes!$B$2:$B$60,"<="&$A9,Equipes!$C$2:$C$60,">="&$A9) -> 0 | Q9: =IF(P9>0,ROUNDUP(P9/Parametres!$B$7,0)+1,0) -> 0
A10: 46091 | B10: =SUMIFS(Equipes!$D$2:$D$60,Equipes!$A$2:$A$60,"LOT-01",Equipes!$B$2:$B$60,"<="&$A10,Equipes!$C$2:$C$60,">="&$A10) -> 5 | C10: =IF(B10>0,ROUNDUP(B10/Parametres!$B$7,0)+1,0) -> 2 | D10: =SUMIFS(Equipes!$D$2:$D$60,Equipes!$A$2:$A$60,"LOT-02",Equipes!$B$2:$B$60,"<="&$A10,Equipes!$C$2:$C$60,">="&$A10) -> 0 | E10: =IF(D10>0,ROUNDUP(D10/Parametres!$B$7,0)+1,0) -> 0 | F10: =SUMIFS(Equipes!$D$2:$D$60,Equipes!$A$2:$A$60,"LOT-03",Equipes!$B$2:$B$60,"<="&$A10,Equipes!$C$2:$C$60,">="&$A10) -> 0 | G10: =IF(F10>0,ROUNDUP(F10/Parametres!$B$7,0)+1,0) -> 0 | H10: =SUMIFS(Equipes!$D$2:$D$60,Equipes!$A$2:$A$60,"LOT-04",Equipes!$B$2:$B$60,"<="&$A10,Equipes!$C$2:$C$60,">="&$A10) -> 0 | I10: =IF(H10>0,ROUNDUP(H10/Parametres!$B$7,0)+1,0) -> 0 | J10: =SUMIFS(Equipes!$D$2:$D$60,Equipes!$A$2:$A$60,"LOT-05",Equipes!$B$2:$B$60,"<="&$A10,Equipes!$C$2:$C$60,">="&$A10) -> 0 | K10: =IF(J10>0,ROUNDUP(J10/Parametres!$B$7,0)+1,0) -> 0 | L10: =SUMIFS(Equipes!$D$2:$D$60,Equipes!$A$2:$A$60,"LOT-06",Equipes!$B$2:$B$60,"<="&$A10,Equipes!$C$2:$C$60,">="&$A10) -> 0 | M10: =IF(L10>0,ROUNDUP(L10/Parametres!$B$7,0)+1,0) -> 0 | N10: =SUMIFS(Equipes!$D$2:$D$60,Equipes!$A$2:$A$60,"LOT-07",Equipes!$B$2:$B$60,"<="&$A10,Equipes!$C$2:$C$60,">="&$A10) -> 0 | O10: =IF(N10>0,ROUNDUP(N10/Parametres!$B$7,0)+1,0) -> 0 | P10: =SUMIFS(Equipes!$D$2:$D$60,Equipes!$A$2:$A$60,"LOT-08",Equipes!$B$2:$B$60,"<="&$A10,Equipes!$C$2:$C$60,">="&$A10) -> 0 | Q10: =IF(P10>0,ROUNDUP(P10/Parametres!$B$7,0)+1,0) -> 0
